Workbook

Sheet resumen
C2: GAS NATURAL
C3: COMPARATIVA
C5: U$S/mm3 | D5: % | J5: U$S /lt-kg | K5: % | O5: mm3 / lt-kg
B6: 2023 | C6: ='datos 23'!I19 -> 196.55574 | I6: 2023 | J6: ='datos 23'!K19 -> 0.0078545589 | N6: 2023 | O6: ='datos 23'!L19 -> 3.3562057e-05
B7: 2024 | C7: ='datos 24'!I19 -> 182.74692 | D7: =(C7-C6)/C6*100 -> -7.025399 | I7: 2024 | J7: ='datos 24'!K19 -> 0.0072825165 | K7: =(J7-J6)/J6*100 -> -7.2829349 | N7: 2024 | O7: ='datos 24'!L19 -> 3.4209829e-05
B8: 2025 | C8: ='datos 25'!I19 -> 201.94029 | D8: =(C8-C7)/C7*100 -> 10.502709 | I8: 2025 | J8: ='datos 25'!K19 -> 0.0091150513 | K8: =(J8-J7)/J7*100 -> 25.163483 | N8: 2025 | O8: ='datos 25'!L19 -> 3.8965038e-05
B9: 2026 | C9: ='datos 26'!I19 -> 217.62093 | D9: =(C9-C8)/C8*100 -> 7.7649842 | I9: enero-marzo 2026 | J9: ='datos 26'!K19 -> 0.013031439 | K9: =(J9-J8)/J8*100 -> 42.966164 | N9: 2026 | O9: ='datos 26'!L19 -> 5.988137e-05
C28: consumo mm3
C29: 2023 | D29: 2024 | E29: 2025 | F29: 2026
B30: enero | C30: ='datos 23'!C5 -> 43.38383 | D30: ='datos 24'!C5 -> 72.633 | E30: ='datos 25'!C5 -> 67.183 | F30: ='datos 26'!C5 -> 60.089
B31: febrero | C31: ='datos 23'!C6 -> 74.46603 | D31: ='datos 24'!C6 -> 83.3 | E31: ='datos 25'!C6 -> 69.047 | F31: ='datos 26'!C6 -> 82.33602
B32: marzo | C32: ='datos 23'!C7 -> 101.79547 | D32: ='datos 24'!C7 -> 81.18 | E32: ='datos 25'!C7 -> 75.359 | F32: ='datos 26'!C7 -> 115.868
B33: abril | C33: ='datos 23'!C8 -> 80.06237 | E33: ='datos 25'!C8 -> 95.974
B34: mayo | C34: ='datos 23'!C9 -> 68.74683 | E34: ='datos 25'!C9 -> 113.788
B35: junio | C35: ='datos 23'!C10 -> 37.76531 | E35: ='datos 25'!C10 -> 108.104
B36: julio | C36: ='datos 23'!C11 -> 127.90123 | E36: ='datos 25'!C11 -> 93.186
B37: agosto | C37: ='datos 23'!C12 -> 131.69097 | E37: ='datos 25'!C12 -> 91.877
B38: septiembre | C38: ='datos 23'!C13 -> 115.90814 | E38: ='datos 25'!C13 -> 91.804
B39: octubre | C39: ='datos 23'!C14 -> 92.036 | E39: ='datos 25'!C14 -> 86.868
B40: noviembre | C40: ='datos 23'!C15 -> 88.197 | E40: ='datos 25'!C15 -> 85.439
B41: diciembre | C41: ='datos 23'!C16 -> 25.907 | D41: ='datos 24'!C16 -> 40.941 | E41: ='datos 25'!C16 -> 57.181

Sheet datos 23
B2: GAS 2023
N3: con fondo | O3: sin fondo
C4: mm3 | D4: $ fondo | E4: $ x U$S | F4: U$S fondo | G4: U$S fact | H4: U$S | I4: U$S / mm3 | J4: lts- kg | K4: U$S / lt-kg | L4: mm3 / lt-kg | M4: MBTU | N4: U$S/MBTU | O4: U$S/MBTU
B5: enero | C5: =11.85776+31.52607 -> 43.38383 | D5: =21037.7+55932.66 -> 76970.36 | E5: 184 | F5: =D5/E5 -> 418.31717 | G5: =2056.82+5468.43 -> 7525.25 | H5: =F5+G5 -> 7943.5672 | I5: =H5/C5 -> 183.09972 | J5: 1114850 | K5: =H5/J5 -> 0.007125234 | L5: =C5/J5 -> 3.89145e-05 | M5: =C5*35.07 -> 1521.4709 | N5: =H5/M5 -> 5.2209786 | O5: =G5/M5 -> 4.946036
B6: febrero | C6: =20.3532+54.11283 -> 74.46603 | D6: =38080.55+101244.33 -> 139324.88 | E6: 204 | F6: =D6/E6 -> 682.9651 | G6: =3530.41+9386.27 -> 12916.68 | H6: =F6+G6 -> 13599.645 | I6: =H6/C6 -> 182.62885 | J6: 2329571 | K6: =H6/J6 -> 0.0058378324 | L6: =C6/J6 -> 3.1965555e-05 | M6: =C6*35.07 -> 2611.5237 | N6: =H6/M6 -> 5.2075519 | O6: =G6/M6 -> 4.9460321
B7: marzo | C7: =27.82294+73.97253 -> 101.79547 | D7: =55453.59+147433.81 -> 202887.4 | E7: 215 | F7: =D7/E7 -> 943.66233 | G7: =4826.09+12831.08 -> 17657.17 | H7: =F7+G7 -> 18600.832 | I7: =H7/C7 -> 182.72751 | J7: 1751127 | K7: =H7/J7 -> 0.010622206 | L7: =C7/J7 -> 5.8131403e-05 | M7: =C7*35.07 -> 3569.9671 | N7: =H7/M7 -> 5.2103651 | O7: =G7/M7 -> 4.9460315
B8: abril | C8: =21.88281+58.17956 -> 80.06237 | D8: =46717.89+124208.29 -> 170926.18 | E8: 230 | F8: =D8/E8 -> 743.1573 | G8: =3795.73+10091.67 -> 13887.4 | H8: =F8+G8 -> 14630.557 | I8: =H8/C8 -> 182.7395 | J8: 2720075 | K8: =H8/J8 -> 0.0053787331 | L8: =C8/J8 -> 2.9433883e-05 | M8: =C8*35.07 -> 2807.7873 | N8: =H8/M8 -> 5.2107071 | O8: =G8/M8 -> 4.9460299
B9: mayo | C9: =18.79002+49.95681 -> 68.74683 | D9: =49399.94+131339.06 -> 180739 | E9: 244 | F9: =D9/E9 -> 740.73361 | G9: =3744.69+9955.96 -> 13700.65 | H9: =F9+G9 -> 14441.384 | I9: =H9/C9 -> 210.06617 | J9: 1147140 | K9: =H9/J9 -> 0.012589033 | L9: =C9/J9 -> 5.9928893e-05 | M9: =C9*35.07 -> 2410.9513 | N9: =H9/M9 -> 5.9899109 | O9: =G9/M9 -> 5.6826738
B10: junio | C10: =10.32209+27.44322 -> 37.76531 | D10: =29207.58+77653.86 -> 106861.44 | E10: 257 | F10: =D10/E10 -> 415.80327 | G10: =2057.1+5469.2 -> 7526.3 | H10: =F10+G10 -> 7942.1033 | I10: =H10/C10 -> 210.30155 | J10: 2441754 | K10: =H10/J10 -> 0.0032526222 | L10: =C10/J10 -> 1.5466468e-05 | M10: =C10*35.07 -> 1324.4294 | N10: =H10/M10 -> 5.9966225 | O10: =G10/M10 -> 5.6826735
B11: julio | C11: =34.95822+92.94301 -> 127.90123 | D11: =107332.2+285362.87 -> 392695.07 | E11: 286 | F11: =D11/E11 -> 1373.0597 | G11: =6966.87+18522.74 -> 25489.61 | H11: =F11+G11 -> 26862.67 | I11: =H11/C11 -> 210.02667 | J11: 2751160 | K11: =H11/J11 -> 0.0097641248 | L11: =C11/J11 -> 4.6489928e-05 | M11: =C11*35.07 -> 4485.4961 | N11: =H11/M11 -> 5.9887845 | O11: =G11/M11 -> 5.6826735
B12: agosto | C12: =35.99404+95.69693 -> 131.69097 | D12: =136560.18+363070.93 -> 499631.11 | E12: 365 | F12: =D12/E12 -> 1368.8524 | G12: =7173.3+19071.58 -> 26244.88 | H12: =F12+G12 -> 27613.732 | I12: =H12/C12 -> 209.68585 | J12: 3263219 | K12: =H12/J12 -> 0.0084621144 | L12: =C12/J12 -> 4.0356154e-05 | M12: =C12*35.07 -> 4618.4023 | N12: =H12/M12 -> 5.979066 | O12: =G12/M12 -> 5.6826751
B13: septiembre | C13: =31.68024+84.2279 -> 115.90814 | D13: =120245.28+319694.79 -> 439940.07 | E13: 367.1 | F13: =D13/E13 -> 1198.4202 | G13: =6313.6+16785.9 -> 23099.5 | H13: =F13+G13 -> 24297.92 | I13: =H13/C13 -> 209.63084 | J13: 2874751 | K13: =H13/J13 -> 0.0084521826 | L13: =C13/J13 -> 4.0319367e-05 | M13: =C13*35.07 -> 4064.8985 | N13: =H13/M13 -> 5.9774975 | O13: =G13/M13 -> 5.6826758
B14: octubre | C14: =66.881+25.155 -> 92.036 | D14: =95452.6+253778.76 -> 349231.36 | E14: 365.5 | F14: =D14/E14 -> 955.48936 | G14: =5013.27+13328.72 -> 18341.99 | H14: =F14+G14 -> 19297.479 | I14: =H14/C14 -> 209.67316 | J14: 2692960 | K14: =H14/J14 -> 0.007165899 | L14: =C14/J14 -> 3.417652e-05 | M14: =C14*35.07 -> 3227.7025 | N14: =H14/M14 -> 5.9787044 | O14: =G14/M14 -> 5.6826767
B15: noviembre | C15: =64.091+24.106 -> 88.197 | D15: =251845+94725 -> 346570 | E15: 365.5 | F15: =D15/E15 -> 948.20793 | G15: =4804.18+12772.8 -> 17576.98 | H15: =F15+G15 -> 18525.188 | I15: =H15/C15 -> 210.04329 | J15: 1379860 | K15: =H15/J15 -> 0.013425411 | L15: =C15/J15 -> 6.3917354e-05 | M15: =C15*35.07 -> 3093.0688 | N15: =H15/M15 -> 5.9892583 | O15: =G15/M15 -> 5.6826993
B16: diciembre | C16: 25.907 | D16: =227816+85687 -> 313503 | E16: 790 | F16: =D16/E16 -> 396.83924 | G16: =5163.09+1941.97 -> 7105.06 | H16: =F16+G16 -> 7501.8992 | I16: =H16/C16 -> 289.57036 | J16: 1156484 | K16: =H16/J16 -> 0.0064868163 | L16: =C16/J16 -> 2.240152e-05 | M16: =C16*35.07 -> 908.55849 | N16: =H16/M16 -> 8.2569249 | O16: =G16/M16 -> 7.820146
B18: total | C18: =SUM(C5:C16) -> 987.86018 | F18: =SUM(F5:F16) -> 10185.508 | G18: =SUM(G5:G16) -> 191071.47 | H18: =SUM(H5:H16) -> 201256.98 | J18: =SUM(J5:J16) -> 25622951 | M18: =SUM(M5:M16) -> 34644.257
B19: promedio ponderado | H19: =(H5*C5+H6*C6+H7*C7+H8*C8+H9*C9+H10*C10+H11*C11+H12*C12+H13*C13+H14*C14+C15*H15+C16*H16)/C18 -> 19443.806 | I19: =(I5*C5+I6*C6+I7*C7+I8*C8+I9*C9+I10*C10+I11*C11+I12*C12+I13*C13+I14*C14+I15*C15+16*C16)/C18 -> 196.55574 | K19: =(K5*J5+K6*J6+K7*J7+K8*J8+K9*J9+K10*J10+K11*J11+K12*J12+K13*J13+K14*J14+K15*J15+K16*J16)/J18 -> 0.0078545589 | L19: =(L5*J5+L6*J6+L7*J7+L8*J8+L9*J9+L10*J10+L11*L11+L12*J12+L13*J13+L14*J14+L15*J15+J16*L16)/J18 -> 3.3562057e-05 | N19: =(N5*M5+N6*M6+N7*M7+N8*M8+N9*M9+N10*M10+N11*M11+N12*M12+N13*M13+N14*M14+N15*M15+L16*M16)/M18 -> 5.5927048

Sheet graficos 23
B2: consumo gas 2023 | D2: 223
C4: mm3
B5: enero | C5: ='datos 23'!C5 -> 43.38383
B6: febrero | C6: ='datos 23'!C6 -> 74.46603
B7: marzo | C7: ='datos 23'!C7 -> 101.79547
B8: abril | C8: ='datos 23'!C8 -> 80.06237
B9: mayo | C9: ='datos 23'!C9 -> 68.74683
B10: junio | C10: ='datos 23'!C10 -> 37.76531
B11: julio | C11: ='datos 23'!C11 -> 127.90123
B12: agosto | C12: ='datos 23'!C12 -> 131.69097
B13: septiembre | C13: ='datos 23'!C13 -> 115.90814
B14: octubre | C14: ='datos 23'!C14 -> 92.036
B15: noviembre | C15: ='datos 23'!C15 -> 88.197
B16: diciembre | C16: ='datos 23'!C16 -> 25.907
B18: promedio | C18: =AVERAGE(C5:C16) -> 82.321682
B20: costo gas por unidad consumida
C21: U$S /mm3
B22: enero | C22: ='datos 23'!I5 -> 183.09972
B23: febrero | C23: ='datos 23'!I6 -> 182.62885
B24: marzo | C24: ='datos 23'!I7 -> 182.72751
B25: abril | C25: ='datos 23'!I8 -> 182.7395
B26: mayo | C26: ='datos 23'!I9 -> 210.06617
B27: junio | C27: ='datos 23'!I10 -> 210.30155
B28: julio | C28: ='datos 23'!I11 -> 210.02667
B29: agosto | C29: ='datos 23'!I12 -> 209.68585
B30: septiembre | C30: ='datos 23'!I13 -> 209.63084
B31: octubre | C31: ='datos 23'!I14 -> 209.67316
B32: noviembre | C32: ='datos 23'!I15 -> 210.04329
B33: diciembre | C33: ='datos 23'!I16 -> 289.57036
B35: promedio ponderado | C35: ='datos 23'!I19 -> 196.55574
B37: costo unitario de gas por unidad producida
C38: U$S / lt- kg
B39: enero | C39: ='datos 23'!K5 -> 0.007125234
B40: febrero | C40: ='datos 23'!K6 -> 0.0058378324
B41: marzo | C41: ='datos 23'!K7 -> 0.010622206
B42: abril | C42: ='datos 23'!K8 -> 0.0053787331
B43: mayo | C43: ='datos 23'!K9 -> 0.012589033
B44: junio | C44: ='datos 23'!K10 -> 0.0032526222
B45: julio | C45: ='datos 23'!K11 -> 0.0097641248
B46: agosto | C46: ='datos 23'!K12+'datos 23'!K30 -> 0.0084621144
...

Sheet datos 24
B2: GAS 2024
N3: con fondo | O3: sin fondo
C4: mm3 | D4: $ fondo | E4: $ x U$S | F4: U$S fondo | G4: U$S fact | H4: U$S | I4: U$S / mm3 | J4: lts- kg | K4: U$S / lt-kg | L4: mm3/lt-kg | M4: MBTU | N4: U$S/MBTU | O4: U$S/MBTU
B5: enero | C5: =52.781+19.852 -> 72.633 | D5: =475055.69+178680.48 -> 653736.17 | E5: 805.5 | F5: =D5/E5 -> 811.59053 | G5: =10518.72+3956.36+(241503.63/E5) -> 14774.898 | H5: =F5+G5 -> 15586.489 | I5: =H5/C5 -> 214.59239 | J5: 2215275 | K5: =H5/J5 -> 0.007035916 | L5: =C5/J5 -> 3.2787351e-05 | M5: =C5*35.07 -> 2547.2393 | N5: =H5/M5 -> 6.1189731 | O5: =G5/M5 -> 5.8003574
B6: febrero | C6: =22.768+60.532 -> 83.3 | D6: =208822.76+555194.65 -> 764017.41 | E6: 841.7 | F6: =D6/E6 -> 907.70751 | G6: =4537.42+12063.57 -> 16600.99 | H6: =F6+G6 -> 17508.698 | I6: =H6/C6 -> 210.18845 | J6: 2969960 | K6: =H6/J6 -> 0.0058952637 | L6: =C6/J6 -> 2.8047516e-05 | M6: =C6*35.07 -> 2921.331 | N6: =H6/M6 -> 5.9933974 | O6: =G6/M6 -> 5.6826803
B7: marzo | C7: =22.188+58.992 -> 81.18 | D7: =551619.31+207477.99 -> 759097.3 | E7: 858 | F7: =D7/E7 -> 884.72879 | G7: =11756.59+4421.95 -> 16178.54 | H7: =F7+G7 -> 17063.269 | I7: =H7/C7 -> 210.19055 | J7: 1867230 | K7: =H7/J7 -> 0.009138279 | L7: =C7/J7 -> 4.3476165e-05 | M7: =C7*35.07 -> 2846.9826 | N7: =H7/M7 -> 5.9934573 | O7: =G7/M7 -> 5.6826972
B8: abril
B9: mayo
B10: junio
B11: julio
B12: agosto
B13: septiembre
B14: octubre
B15: noviembre
B16: diciembre | C16: =29.751+11.19 -> 40.941 | D16: =334318.18+125745.54 -> 460063.72 | E16: 1036.5 | F16: =D16/E16 -> 443.86273 | G16: =5929.14+((342249.2+103542.47)/1036.5)+2230 -> 8589.2333 | H16: =F16+G16 -> 9033.096 | I16: =H16/C16 -> 220.63692 | J16: 1075433 | K16: =H16/J16 -> 0.0083994968 | L16: =C16/J16 -> 3.8069317e-05 | M16: =C16*35.07 -> 1435.8009 | N16: =H16/M16 -> 6.2913292 | O16: =G16/M16 -> 5.9821898
B18: total | C18: =SUM(C5:C16) -> 278.054 | F18: =SUM(F5:F16) -> 3047.8896 | G18: =SUM(G5:G16) -> 56143.662 | H18: =SUM(H5:H16) -> 59191.551 | J18: =SUM(J5:J16) -> 8127898 | M18: =SUM(M5:M16) -> 9751.3538
A19: promedio ponderado | C19: =(C5*J5+C6*J6+C7*J7+C8*J8+C9*J9+C10*J10+C11*J11+C12*J12+C13*J13+C14*J14+C15*J15+C16*J16)/J18 -> 74.300978 | H19: =(H5*C5+H6*C6+H7*C7+H8*C8+H9*C9+H10*C10+H11*C11+H12*C12+H13*C13+H14*C14+H15*C15+H16*C16)/C18 -> 15628.576 | I19: =(I5*C5+I6*C6+I7*C7+I8*C8+I9*C9+I10*C10+I11*C11+I12*C12+I13*C13+I14*C14+I15*C15+16*C16)/C18 -> 182.74692 | K19: =(K5*J5+K6*J6+K7*J7+K8*J8+K9*J9+K10*J10+K11*J11+K12*J12+K13*J13+K14*J14+K15*J15+K16*J16)/J18 -> 0.0072825165 | L19: =(L5*J5+L6*J6+L7*J7+L8*J8+L9*J9+L10*J10+L11*L11+L12*J12+L13*J13+L14*J14+L15*J15+J16*L16)/J18 -> 3.4209829e-05 | N19: =H18/M18 -> 6.0700855 | O19: =G18/M18 -> 5.7575248

Sheet graficos 24
B1: consumo gas 2024
C3: mm3
B4: enero | C4: ='datos 24'!C5 -> 72.633
B5: febrero | C5: ='datos 24'!C6 -> 83.3
B6: marzo | C6: ='datos 24'!C7 -> 81.18
B7: abril
B8: mayo
B9: junio
B10: julio
B11: agosto
B12: septiembre
B13: octubre
B14: noviembre
B15: diciembre
B17: promedio | C17: ='datos 24'!C19 -> 74.300978
B19: costo gas por unidad consumida | L19: costo gas por unidad consumida
C20: U$S / mm3 | M20: U$S / MBTU
B21: enero | C21: ='datos 24'!I5 -> 214.59239 | L21: enero | M21: ='datos 24'!N5 -> 6.1189731
B22: febrero | C22: ='datos 24'!I6 -> 210.18845 | L22: febrero | M22: ='datos 24'!N6 -> 5.9933974
B23: marzo | C23: ='datos 24'!I7 -> 210.19055 | L23: marzo | M23: ='datos 24'!N7 -> 5.9934573
B24: abril | L24: abril
B25: mayo | L25: mayo
B26: junio | L26: junio
B27: julio | L27: julio
B28: agosto | L28: agosto
B29: septiembre | L29: septiembre
B30: octubre | L30: octubre
B31: noviembre | L31: noviembre
B32: diciembre | L32: diciembre
B34: promedio ponderado | C34: ='datos 24'!I19 -> 182.74692 | L34: promedio ponderado | M34: ='datos 24'!N19 -> 6.0700855
B36: costo unitario de gas por unidad producida
C37: U$S / lt- kg
B38: enero | C38: ='datos 24'!K5 -> 0.007035916
B39: febrero | C39: ='datos 24'!K6 -> 0.0058952637
B40: marzo | C40: ='datos 24'!K7 -> 0.009138279
B41: abril
B42: mayo
B43: junio
B44: julio
B45: agosto
...

Sheet datos 25
B2: GAS 2025
N3: con fondo | O3: sin fondo
C4: mm3 | D4: $ fondo | E4: $ x U$S | F4: U$S fondo | G4: U$S fact | H4: U$S | I4: U$S / mm3 | J4: lts- kg- udad | K4: U$S / lt-kg-udad | L4: mm3/lt-kg | M4: MBTU | N4: U$S/MBTU | O4: U$S/MBTU
B5: enero | C5: =48.823+18.36 -> 67.183 | D5: =559213.74+210334 -> 769547.74 | E5: 1074 | F5: =D5/E5 -> 716.5249 | G5: =9729.92+(254877.72/1056.5)+3660 -> 13631.167 | H5: =F5+G5 -> 14347.692 | I5: =H5/C5 -> 213.56135 | J5: 615394 | K5: =H5/J5 -> 0.023314644 | L5: =C5/J5 -> 0.00010917071 | M5: =C5*35.07 -> 2356.1078 | N5: =H5/M5 -> 6.0895737 | O5: =G5/M5 -> 5.7854599
B6: febrero | C6: =50.177+18.87 -> 69.047 | D6: =580480.08+218333 -> 798813.08 | E6: 1084 | F6: =D6/E6 -> 736.91244 | G6: =9999.94+3761 -> 13760.94 | H6: =F6+G6 -> 14497.852 | I6: =H6/C6 -> 209.97078 | J6: 549630 | K6: =H6/J6 -> 0.026377477 | L6: =C6/J6 -> 0.00012562451 | M6: =C6*35.07 -> 2421.4783 | N6: =H6/M6 -> 5.9871908 | O6: =G6/M6 -> 5.6828674
B7: marzo | C7: =20.597+54.762 -> 75.359 | D7: =240330.71+638964.43 -> 879295.14 | E7: 1094 | F7: =D7/E7 -> 803.74327 | G7: =4105.26+10913.51 -> 15018.77 | H7: =F7+G7 -> 15822.513 | I7: =H7/C7 -> 209.96183 | J7: 571590 | K7: =H7/J7 -> 0.027681578 | L7: =C7/J7 -> 0.000131841 | M7: =C7*35.07 -> 2642.8401 | N7: =H7/M7 -> 5.9869355 | O7: =G7/M7 -> 5.6828144
B8: abril | C8: =69.742+26.232 -> 95.974 | D8: =349425+929012 -> 1278437 | E8: 1114 | F8: =D8/E8 -> 1147.6095 | G8: =13899+5228 -> 19127 | H8: =F8+G8 -> 20274.61 | I8: =H8/C8 -> 211.25106 | J8: 1805204 | K8: =H8/J8 -> 0.011231201 | L8: =C8/J8 -> 5.3165182e-05 | M8: =C8*35.07 -> 3365.8082 | N8: =H8/M8 -> 6.0236973 | O8: =G8/M8 -> 5.6827362
B9: mayo | C9: =30.848+82.94 -> 113.788 | D9: =438388.39+1165538.05 -> 1603926.4 | E9: 1188.5 | F9: =D9/E9 -> 1349.5384 | G9: =16344.66+6147.64 -> 22492.3 | H9: =F9+G9 -> 23841.838 | I9: =H9/C9 -> 209.52858 | J9: 2818877 | K9: =H9/J9 -> 0.0084579208 | L9: =C9/J9 -> 4.036643e-05 | M9: =C9*35.07 -> 3990.5452 | N9: =H9/M9 -> 5.9745818 | O9: =G9/M9 -> 5.6363978
B10: junio | C10: =78.557+29.547 -> 108.104 | D10: =1218167.82+458183.78 -> 1676351.6 | E10: 1213 | F10: =D10/E10 -> 1381.9881 | G10: =15655.67+5888.49 -> 21544.16 | H10: =F10+G10 -> 22926.148 | I10: =H10/C10 -> 212.07493 | J10: 2804727 | K10: =H10/J10 -> 0.0081741104 | L10: =C10/J10 -> 3.8543502e-05 | M10: =C10*35.07 -> 3791.2073 | N10: =H10/M10 -> 6.0471893 | O10: =G10/M10 -> 5.6826648
B11: julio | C11: =25.47+67.716 -> 93.186 | D11: =427330+1136139.41 -> 1563469.4 | E11: 1360 | F11: =D11/E11 -> 1149.6099 | G11: =5076.41+13495.22 -> 18571.63 | H11: =F11+G11 -> 19721.24 | I11: =H11/C11 -> 211.63308 | J11: 3024982 | K11: =H11/J11 -> 0.0065194569 | L11: =C11/J11 -> 3.0805473e-05 | M11: =C11*35.07 -> 3268.033 | N11: =H11/M11 -> 6.0345901 | O11: =G11/M11 -> 5.6828159
B12: agosto | C12: =66.765+25.112 -> 91.877 | D12: =1243937.52+465399.13 -> 1709336.6 | E12: 1409 | F12: =D12/E12 -> 1213.1559 | G12: =5005.11+13305.71 -> 18310.82 | H12: =F12+G12 -> 19523.976 | I12: =H12/C12 -> 212.50123 | J12: 3040436 | K12: =H12/J12 -> 0.0064214395 | L12: =C12/J12 -> 3.0218363e-05 | M12: =C12*35.07 -> 3222.1264 | N12: =H12/M12 -> 6.0593451 | O12: =G12/M12 -> 5.6828373
B13: septiembre | C13: =25.092+66.712 -> 91.804 | D13: =1292821+486262.79 -> 1779083.8 | E13: 1430 | F13: =D13/E13 -> 1244.1145 | G13: =5000.85+13295.16 -> 18296.01 | H13: =F13+G13 -> 19540.125 | I13: =H13/C13 -> 212.84611 | J13: 2896236 | K13: =H13/J13 -> 0.0067467308 | L13: =C13/J13 -> 3.1697693e-05 | M13: =C13*35.07 -> 3219.5663 | N13: =H13/M13 -> 6.0691791 | O13: =G13/M13 -> 5.6827561
B14: octubre | C14: =63.125+23.743 -> 86.868 | D14: =1243431.03+467685.9 -> 1711116.9 | E14: 1412 | F14: =D14/E14 -> 1211.8392 | G14: =5000.85+13295.16 -> 18296.01 | H14: =F14+G14 -> 19507.849 | I14: =H14/C14 -> 224.56888 | J14: 2715838 | K14: =H14/J14 -> 0.0071829944 | L14: =C14/J14 -> 3.1985708e-05 | M14: =C14*35.07 -> 3046.4608 | N14: =H14/M14 -> 6.4034467 | O14: =G14/M14 -> 6.0056608
B15: noviembre | C15: =23.352+62.087 -> 85.439 | D15: =1278417+480485 -> 1758902 | E15: 1435 | F15: =D15/E15 -> 1225.7157 | G15: =12373.38+4653.94 -> 17027.32 | H15: =F15+G15 -> 18253.036 | I15: =H15/C15 -> 213.63822 | J15: 1933070 | K15: =H15/J15 -> 0.0094425115 | L15: =C15/J15 -> 4.4198606e-05 | M15: =C15*35.07 -> 2996.3457 | N15: =H15/M15 -> 6.0917655 | O15: =G15/M15 -> 5.6826954
B16: diciembre | C16: =15.629+41.552 -> 57.181 | D16: =341988.2+909239.98 -> 1251228.2 | E16: 1464 | F16: =D16/E16 -> 854.66406 | G16: =8280.87+3114.65 -> 11395.52 | H16: =F16+G16 -> 12250.184 | I16: =H16/C16 -> 214.23522 | J16: =1094280+321269 -> 1415549 | K16: =H16/J16 -> 0.0086540163 | L16: =C16/J16 -> 4.0394928e-05 | M16: =C16*35.07 -> 2005.3377 | N16: =H16/M16 -> 6.1087887 | O16: =G16/M16 -> 5.6825941
B18: total | C18: =SUM(C5:C16) -> 1035.81 | F18: =SUM(F5:F16) -> 13035.416 | G18: =SUM(G5:G16) -> 207471.65 | H18: =SUM(H5:H16) -> 220507.06 | J18: =SUM(J5:J16) -> 24191533 | M18: =C18*35.07 -> 36325.857
A19: promedio ponderado | C19: =(C5*J5+C6*J6+C7*J7+C8*J8+C9*J9+C10*J10+C11*J11+C12*J12+C13*J13+C14*J14+C15*J15+C16*J16)/J18 -> 92.128004 | H19: =(H5*C5+H6*C6+H7*C7+H8*C8+H9*C9+H10*C10+H11*C11+H12*C12+H13*C13+H14*C14+H15*C15+H16*C16)/C18 -> 18994.312 | I19: =(I5*C5+I6*C6+I7*C7+I8*C8+I9*C9+I10*C10+I11*C11+I12*C12+I13*C13+I14*C14+I15*C15+16*C16)/C18 -> 201.94029 | K19: =(K5*J5+K6*J6+K7*J7+K8*J8+K9*J9+K10*J10+K11*J11+K12*J12+K13*J13+K14*J14+K15*J15+K16*J16)/J18 -> 0.0091150513 | L19: =(L5*J5+L6*J6+L7*J7+L8*J8+L9*J9+L10*J10+L11*L11+L12*J12+L13*J13+L14*J14+L15*J15+J16*L16)/J18 -> 3.8965038e-05 | N19: =H18/M18 -> 6.0702509 | O19: =G18/M18 -> 5.7114041
B22: GAS 2025
C24: mm3 | D24: U$S | E24: U$S / mm3 | F24: lts- kg-udad | G24: U$S / lt-kg-udad
B25: enero | C25: =C5 -> 67.183 | D25: =H5 -> 14347.692 | E25: =I5 -> 213.56135 | F25: =J5 -> 615394 | G25: =K5 -> 0.023314644
B26: febrero | C26: =C6 -> 69.047 | D26: =H6 -> 14497.852 | E26: =I6 -> 209.97078 | F26: =J6 -> 549630 | G26: =K6 -> 0.026377477
B27: marzo | C27: =C7 -> 75.359 | D27: =H7 -> 15822.513 | E27: =I7 -> 209.96183 | F27: =J7 -> 571590 | G27: =K7 -> 0.027681578
B28: abril | C28: =C8 -> 95.974 | D28: =H8 -> 20274.61 | E28: =I8 -> 211.25106 | F28: =J8 -> 1805204 | G28: =K8 -> 0.011231201
B29: mayo | C29: =C9 -> 113.788 | D29: =H9 -> 23841.838 | E29: =I9 -> 209.52858 | F29: =J9 -> 2818877 | G29: =K9 -> 0.0084579208
B30: junio | C30: =C10 -> 108.104 | D30: =H10 -> 22926.148 | E30: =I10 -> 212.07493 | F30: =J10 -> 2804727 | G30: =K10 -> 0.0081741104
B31: julio | C31: =C11 -> 93.186 | D31: =H11 -> 19721.24 | E31: =I11 -> 211.63308 | F31: 3024982 | G31: =K11 -> 0.0065194569
B32: agosto | C32: =C12 -> 91.877 | D32: =H12 -> 19523.976 | E32: =I12 -> 212.50123 | F32: 3040436 | G32: =K12 -> 0.0064214395
B33: septiembre | C33: =C13 -> 91.804 | D33: =H13 -> 19540.125 | E33: =I13 -> 212.84611 | F33: 2896236 | G33: =K13 -> 0.0067467308
B34: octubre | C34: =C14 -> 86.868 | D34: =H14 -> 19507.849 | E34: =I14 -> 224.56888 | F34: 2715838 | G34: =K14 -> 0.0071829944
B35: noviembre | C35: =C15 -> 85.439 | D35: =H15 -> 18253.036 | E35: =I15 -> 213.63822 | F35: 1933070 | G35: =K15 -> 0.0094425115
B36: diciembre | C36: =C16 -> 57.181 | D36: =H16 -> 12250.184 | E36: =I16 -> 214.23522 | F36: =J16 -> 1415549 | G36: =K16 -> 0.0086540163
B37: promedio ponderado | E37: =I19 -> 201.94029 | G37: =K19 -> 0.0091150513

Sheet graficos 25
B1: consumo gas 2025
C3: mm3
B4: enero | C4: ='datos 25'!C5 -> 67.183
B5: febrero | C5: ='datos 25'!C6 -> 69.047
B6: marzo | C6: ='datos 25'!C7 -> 75.359
B7: abril | C7: ='datos 25'!C8 -> 95.974
B8: mayo | C8: ='datos 25'!C9 -> 113.788
B9: junio | C9: ='datos 25'!C10 -> 108.104
B10: julio | C10: ='datos 25'!C11 -> 93.186
B11: agosto | C11: ='datos 25'!C12 -> 91.877
B12: septiembre | C12: ='datos 25'!C13 -> 91.804
B13: octubre | C13: ='datos 25'!C14 -> 86.868
B14: noviembre | C14: ='datos 25'!C15 -> 85.439
B15: diciembre | C15: ='datos 25'!C16 -> 57.181
B17: promedio | C17: ='datos 25'!C19 -> 92.128004
B19: costo gas por unidad consumida | L19: costo gas por unidad consumida
C20: U$S / mm3 | M20: U$S / MBTU
B21: enero | C21: ='datos 25'!I5 -> 213.56135 | L21: enero | M21: ='datos 25'!N5 -> 6.0895737
B22: febrero | C22: ='datos 25'!I6 -> 209.97078 | L22: febrero | M22: ='datos 25'!N6 -> 5.9871908
B23: marzo | C23: ='datos 25'!I7 -> 209.96183 | L23: marzo | M23: ='datos 25'!N7 -> 5.9869355
B24: abril | C24: ='datos 25'!I8 -> 211.25106 | L24: abril | M24: ='datos 25'!N8 -> 6.0236973
B25: mayo | C25: ='datos 25'!I9 -> 209.52858 | L25: mayo | M25: ='datos 25'!N9 -> 5.9745818
B26: junio | C26: ='datos 25'!I10 -> 212.07493 | L26: junio | M26: ='datos 25'!N10 -> 6.0471893
B27: julio | C27: ='datos 25'!I11 -> 211.63308 | L27: julio | M27: ='datos 25'!N11 -> 6.0345901
B28: agosto | C28: ='datos 25'!I12 -> 212.50123 | L28: agosto | M28: ='datos 25'!N12 -> 6.0593451
B29: septiembre | C29: ='datos 25'!I13 -> 212.84611 | L29: septiembre | M29: ='datos 25'!N13 -> 6.0691791
B30: octubre | C30: ='datos 25'!I14 -> 224.56888 | L30: octubre | M30: ='datos 25'!N14 -> 6.4034467
B31: noviembre | C31: ='datos 25'!I15 -> 213.63822 | L31: noviembre | M31: ='datos 25'!N15 -> 6.0917655
B32: diciembre | C32: ='datos 25'!I16 -> 214.23522 | L32: diciembre | M32: ='datos 25'!N16 -> 6.1087887
B34: promedio ponderado | C34: ='datos 25'!I19 -> 201.94029 | L34: promedio ponderado | M34: ='datos 25'!N19 -> 6.0702509
B36: costo unitario de gas por unidad producida
C37: U$S / lt- kg
B38: enero | C38: ='datos 25'!K5 -> 0.023314644
B39: febrero | C39: ='datos 25'!K6 -> 0.026377477
B40: marzo | C40: ='datos 25'!K7 -> 0.027681578
B41: abril | C41: ='datos 25'!K8 -> 0.011231201
B42: mayo | C42: ='datos 25'!K9 -> 0.0084579208
B43: junio | C43: ='datos 25'!K10 -> 0.0081741104
B44: julio | C44: ='datos 25'!K11 -> 0.0065194569
B45: agosto | C45: ='datos 25'!K12 -> 0.0064214395
...

Sheet datos 26
B2: GAS 2026
J3: mes calendario | N3: con fondo | O3: sin fondo
C4: mm3 | D4: $ fondo | E4: $ x U$S | F4: U$S fondo | G4: U$S fact | H4: U$S | I4: U$S / mm3 | J4: lts- kg- udad | K4: U$S / lt-kg-udad | L4: mm3/lt-kg | M4: MBTU | N4: U$S/MBTU | O4: U$S/MBTU
B5: enero | C5: =43.665+16.424 -> 60.089 | D5: =941133.8+353984.25 -> 1295118.1 | E5: 1470 | F5: =D5/E5 -> 881.03269 | G5: =8702.12+3273.09 -> 11975.21 | H5: =F5+G5 -> 12856.243 | I5: =H5/C5 -> 213.95335 | J5: =931160+262742 -> 1193902 | K5: =H5/J5 -> 0.010768256 | L5: =C5/J5 -> 5.0329927e-05 | M5: =C5*35.07 -> 2107.3212 | N5: =H5/M5 -> 6.1007513 | O5: =G5/M5 -> 5.6826695
B6: febrero | C6: =82336.02/1000 -> 82.33602 | D6: =476295.69+2496269.08 -> 2972564.8 | E6: 1425 | F6: =D6/E6 -> 2086.0104 | G6: =4484.89+11923.93 -> 16408.82 | H6: =F6+G6 -> 18494.83 | I6: =H6/C6 -> 224.62624 | J6: 1331328 | K6: =H6/J6 -> 0.013892016 | L6: =C6/J6 -> 6.184503e-05 | M6: =C6*35.07 -> 2887.5242 | N6: =H6/M6 -> 6.4050823 | O6: =G6/M6 -> 5.6826606
B7: marzo | C7: =84.199+31.669 -> 115.868 | D7: =670271.13+1782042.03 -> 2452313.2 | E7: 1387.5 | F7: =D7/E7 -> 1767.4329 | G7: =6311.4+16780.06 -> 23091.46 | H7: =F7+G7 -> 24858.893 | I7: =H7/C7 -> 214.54494 | J7: 1788182 | K7: =H7/J7 -> 0.013901769 | L7: =C7/J7 -> 6.4796536e-05 | M7: =C7*35.07 -> 4063.4908 | N7: =H7/M7 -> 6.1176201 | O7: =G7/M7 -> 5.6826658
B8: abril | M8: =C8*35.07 -> 0
B9: mayo | M9: =C9*35.07 -> 0
B10: junio | M10: =C10*35.07 -> 0
B11: julio | M11: =C11*35.07 -> 0
B12: agosto | M12: =C12*35.07 -> 0
B13: septiembre | M13: =C13*35.07 -> 0
B14: octubre | M14: =C14*35.07 -> 0
B15: noviembre | M15: =C15*35.07 -> 0
B16: diciembre | M16: =C16*35.07 -> 0
B18: total | C18: =SUM(C5:C16) -> 258.29302 | F18: =SUM(F5:F16) -> 4734.476 | G18: =SUM(G5:G16) -> 51475.49 | H18: =SUM(H5:H16) -> 56209.966 | J18: =SUM(J5:J16) -> 4313412 | M18: =C18*35.07 -> 9058.3362
A19: promedio ponderado | C19: =(C5*J5+C6*J6+C7*J7+C8*J8+C9*J9+C10*J10+C11*J11+C12*J12+C13*J13+C14*J14+C15*J15+C16*J16)/J18 -> 90.079431 | H19: =(H5*C5+H6*C6+H7*C7+H8*C8+H9*C9+H10*C10+H11*C11+H12*C12+H13*C13+H14*C14+H15*C15+H16*C16)/C18 -> 20037.939 | I19: =(I5*C5+I6*C6+I7*C7+I8*C8+I9*C9+I10*C10+I11*C11+I12*C12+I13*C13+I14*C14+I15*C15+16*C16)/C18 -> 217.62093 | K19: =(K5*J5+K6*J6+K7*J7+K8*J8+K9*J9+K10*J10+K11*J11+K12*J12+K13*J13+K14*J14+K15*J15+K16*J16)/J18 -> 0.013031439 | L19: =(L5*J5+L6*J6+L7*J7+L8*J8+L9*J9+L10*J10+L11*L11+L12*J12+L13*J13+L14*J14+L15*J15+J16*L16)/J18 -> 5.988137e-05 | N19: =H18/M18 -> 6.2053301 | O19: =G18/M18 -> 5.682665
B22: GAS 2026
I23: con fondo
C24: mm3 | D24: U$S | E24: U$S / mm3 | F24: lts- kg-udad | G24: U$S / lt-kg-udad | H24: MBTU | I24: U$S/MBTU
B25: enero | C25: =C5 -> 60.089 | D25: =H5 -> 12856.243 | E25: =I5 -> 213.95335 | F25: =J5 -> 1193902 | G25: =K5 -> 0.010768256 | H25: =C25*35.07 -> 2107.3212 | I25: =D25/H25 -> 6.1007513
B26: febrero | C26: =C6 -> 82.33602 | D26: =H6 -> 18494.83 | E26: =I6 -> 224.62624 | F26: =J6 -> 1331328 | G26: =K6 -> 0.013892016 | H26: =C26*35.07 -> 2887.5242 | I26: =D26/H26 -> 6.4050823
B27: marzo | C27: =C7 -> 115.868 | D27: =H7 -> 24858.893 | E27: =I7 -> 214.54494 | F27: =J7 -> 1788182 | G27: =K7 -> 0.013901769 | H27: =C27*35.07 -> 4063.4908 | I27: =D27/H27 -> 6.1176201
B28: abril
B29: mayo
B30: junio
B31: julio
B32: agosto
B33: septiembre
B34: octubre
B35: noviembre
B36: diciembre
B37: promedio ponderado | E37: =I19 -> 217.62093 | G37: =K19 -> 0.013031439
B38: 2025

Sheet graficos 26
B1: consumo gas 2026
C3: mm3
B4: enero | C4: ='datos 26'!C5 -> 60.089
B5: febrero | C5: ='datos 26'!C6 -> 82.33602
B6: marzo
B7: abril
B8: mayo
B9: junio
B10: julio
B11: agosto
B12: septiembre
B13: octubre
B14: noviembre
B15: diciembre
B17: promedio | C17: ='datos 26'!C19 -> 90.079431
B19: costo gas por unidad consumida
C20: U$S / mm3
B21: enero | C21: ='datos 26'!I5 -> 213.95335
B22: febrero | C22: ='datos 26'!I6 -> 224.62624
B23: marzo
B24: abril
B25: mayo
B26: junio
B27: julio
B28: agosto
B29: septiembre
B30: octubre
B31: noviembre
B32: diciembre
B34: promedio ponderado | C34: ='datos 26'!I19 -> 217.62093
B36: costo unitario de gas por unidad producida
C37: U$S / lt- kg
B38: enero | C38: ='datos 26'!K5 -> 0.010768256
B39: febrero | C39: ='datos 26'!K6 -> 0.013892016
B40: marzo | C40: ='datos 26'!K7 -> 0.013901769
B41: abril
B42: mayo
B43: junio
B44: julio
B45: agosto
...

Sheet precios
B2: VALORES INTERNACIONALES DE GAS NATURAL PARA NEGOCIOS | I2: VALORES ARGENTINA DE GAS NATURAL INDUSTRIAS
B3: fuente : The Wall Street Journal - World Bank | I3: fuente : Dirección Nacional de la Economia de Hidrocarburos - Res 1/2018
C4: U$S / MBTU | D4: promedio | J4: U$S / MBTU | K4: promedio anual | L4: TdF
B5: 44562 | C5: 4.33 | I5: 44562 | J5: 2.67
B6: febrero | C6: 4.66 | I6: febrero | J6: 2.64
B7: marzo | C7: 4.88 | I7: marzo | J7: 2.63
B8: abril | C8: 6.53 | I8: abril | J8: 2.65
B9: mayo | C9: 8.14 | I9: mayo | J9: 3.67
B10: junio | C10: 7.67 | I10: junio | J10: 3.63
B11: julio | C11: 7.26 | I11: julio | J11: 3.56
B12: agosto | C12: 8.79 | I12: agosto | J12: 3.53
B13: septiembre | C13: 7.76 | I13: septiembre | J13: 3.55
B14: octubre | C14: 5.62 | I14: octubre | J14: 2.66
B15: noviembre | C15: 5.28 | I15: noviembre | J15: 2.73
B16: diciembre | C16: 5.5 | D16: =AVERAGE(C5:C16) -> 6.3683333 | I16: diciembre | J16: 2.72
K17: 3.05
B18: 44927 | C18: 3.27 | I18: 44927 | J18: 2.8
B19: febrero | C19: 2.38 | I19: febrero | J19: 2.79
B20: marzo | C20: 2.3 | I20: marzo | J20: 2.87
B21: abril | C21: 2.16 | I21: abril | J21: 2.81
B22: mayo | C22: 2.15 | I22: mayo | J22: 3.73
B23: junio | C23: 2.18 | I23: junio | J23: 3.43
B24: julio | C24: 2.55 | I24: julio | J24: 3.56
B25: agosto | C25: 2.58 | I25: agosto | J25: 3.45
B26: septiembre | C26: 2.64 | I26: septiembre | J26: 3.72
B27: octubre | C27: 2.99 | I27: octubre | J27: 2.66
B28: noviembre | C28: 2.71 | I28: noviembre | J28: 3.38
B29: diciembre | C29: 2.53 | D29: =AVERAGE(C18:C29) -> 2.5366667 | I29: diciembre | J29: 2.31
K30: 3.13 | L30: 5.59
B32: 45292 | C32: 3.18 | I32: 45292 | J32: 2.56
B33: febrero | C33: 1.72 | D33: =AVERAGE(C20:C33) -> 2.4741667 | L33: 6.12
I34: 2025 | J34: sin datos | L34: 6.07
I36: 46023 | J36: sin datos | L36: 6.1
