Workbook

Sheet resumen
C2: ENERGIA ELECTRICA
C3: COMPARATIVA
L4: ENERGIA
C5: U$S/KW | D5: % | E5: U$S /lt-kg | F5: % | G5: KW / lt-kg | H5: % | L5: U$S/KW | M5: U$S /lt-kg | N5: KW / lt-kg
B6: 2023 | C6: =datos23!G56 -> 0.098000567 | E6: =datos23!I56 -> 0.017020672 | G6: =datos23!J56 -> 0.16541384 | I6: promedio con 2 medidores | K6: 2023 | L6: =C6 -> 0.098000567 | M6: =E6 -> 0.017020672 | N6: =G6 -> 0.16541384
B7: 2024 | C7: =datos24!G56 -> 0.16341625 | D7: =(C7-C6)/C6*100 -> 66.750311 | E7: =datos24!I56 -> 0.023061191 | F7: =(E7-E6)/E6*100 -> 35.489306 | G7: =datos24!J56 -> 0.13333579 | H7: =(G7-G6)/G6*100 -> -19.392606 | K7: 2024 | L7: =C7 -> 0.16341625 | M7: =E7 -> 0.023061191 | N7: 0.1633
B8: 2025 | C8: =datos25!G56 -> 0.18298168 | D8: =(C8-C7)/C7*100 -> 11.972756 | E8: =datos25!I56 -> 0.033378505 | F8: =(E8-E7)/E7*100 -> 44.738862 | G8: =datos25!J56 -> 0.16644185 | H8: =(G8-G7)/G7*100 -> 24.829089 | K8: 2025 | L8: =C8 -> 0.18298168 | M8: =E8 -> 0.033378505 | N8: =G8 -> 0.16644185
B9: 2026 | C9: =datos26!G56 -> 0 | D9: =(C9-C8)/C8*100 -> -100 | E9: =datos26!I56 -> 0 | F9: =(E9-E8)/E8*100 -> -100 | G9: =datos26!J56 -> 0 | H9: =(G9-G8)/G8*100 -> -100 | K9: 2026 | L9: =C9 -> 0 | M9: =E9 -> 0 | N9: =G9 -> 0
C11: U$S/KW | D11: % | E11: U$S /lt-kg | F11: % | G11: KW / lt-kg | H11: % | L11: U$S/KW | M11: U$S /lt-kg | N11: KW / lt-kg
B12: 2023 | C12: =datos23!G19 -> 0.084701112 | E12: =datos23!I19 -> 0.013540316 | G12: =datos23!J19 -> 0.14423042 | I12: medidor de producción | K12: 2023 | L12: =C12 -> 0.084701112 | M12: =E12 -> 0.013540316 | N12: =G12 -> 0.14423042
B13: 2024 | C13: =datos24!G19 -> 0.13337968 | D13: =(C13-C12)/C12*100 -> 57.470994 | E13: =datos24!I19 -> 0.018826241 | F13: =(E13-E12)/E12*100 -> 39.03842 | G13: =datos24!J19 -> 0.13266517 | H13: =(G13-G12)/G12*100 -> -8.0185933 | K13: 2024 | L13: =C13 -> 0.13337968 | M13: =E13 -> 0.018826241 | N13: =G13 -> 0.13266517
B14: 2025 | C14: =datos25!G19 -> 0.18231925 | D14: =(C14-C13)/C13*100 -> 36.691921 | E14: =datos25!I19 -> 0.023351891 | F14: =(E14-E13)/E13*100 -> 24.039051 | G14: =datos25!J19 -> 0.11585072 | H14: =(G14-G13)/G13*100 -> -12.674352 | K14: 2025 | L14: =C14 -> 0.18231925 | M14: =E14 -> 0.023351891 | N14: =G14 -> 0.11585072
B15: 2026 | C15: =datos26!F17 -> 0.18498759 | D15: =(C15-C14)/C14*100 -> 1.4635559 | E15: =datos26!H17 -> 0.043645391 | F15: =(E15-E14)/E14*100 -> 86.903028 | G15: =datos26!I17 -> 0.23814503 | H15: =(G15-G14)/G14*100 -> 105.56197 | K15: 2026 | L15: =C15 -> 0.18498759 | M15: =E15 -> 0.043645391 | N15: =G15 -> 0.23814503
C17: U$S/KW | D17: % | E17: U$S /udad | F17: % | G17: KW / udad | H17: % | L17: U$S/KW | M17: U$S /udad | N17: KW / udad
B18: 2023 | C18: =datos23!G37 -> 1.0120662 | E18: =datos23!I37 -> 0.58745941 | G18: =datos23!J37 -> 1.2046942 | I18: medidor de sopladoras | K18: 2023 | L18: =C18 -> 1.0120662 | M18: =E18 -> 0.58745941 | N18: =G18 -> 1.2046942
B19: 2024 | C19: =datos24!G37 -> 3.0574801 | D19: =(C19-C18)/C18*100 -> 202.10276 | E19: =datos24!I37 -> 0.73639433 | F19: =(E19-E18)/E18*100 -> 25.352378 | G19: =datos24!J37 -> 0.24235061 | H19: =(G19-G18)/G18*100 -> -79.882811 | K19: 2024 | L19: =C19 -> 3.0574801 | M19: =E19 -> 0.73639433 | N19: =G19 -> 0.24235061
B20: 2025 | C20: =datos25!G37 -> 0.19465288 | D20: =(C20-C19)/C19*100 -> -93.633552 | E20: =datos25!I37 -> 0.086667205 | F20: =(E20-E19)/E19*100 -> -88.23087 | G20: =datos25!J37 -> 0.42989244 | H20: =(G20-G19)/G19*100 -> 77.384515 | K20: 2025 | L20: =C20 -> 0.19465288 | M20: =E20 -> 0.086667205 | N20: =G20 -> 0.42989244
B21: 2026 | C21: =datos26!F35 -> 0 | D21: =(C21-C20)/C20*100 -> -100 | E21: =datos26!H35 -> 0 | F21: =(E21-E20)/E20*100 -> -100 | G21: =datos26!I35 -> 0 | H21: =(G21-G20)/G20*100 -> -100 | K21: 2026 | L21: =C21 -> 0 | M21: =E21 -> 0 | N21: =G21 -> 0

Sheet datos23
B2: ENERGIA ELECTRICA 2023
B3: medidor | C3: 4156946
C4: Kw-h | D4: $ | E4: $ x U$S | F4: U$S | G4: U$S / Kw-h | H4: lts- kg | I4: U$S / lt-kg | J4: Kw-h / lt-kg
B5: enero | C5: 264947 | D5: 3594025 | E5: 184 | F5: =D5/E5 -> 19532.745 | G5: =F5/C5 -> 0.073723215 | H5: 1114850 | I5: =F5/H5 -> 0.017520514 | J5: =C5/H5 -> 0.2376526
B6: febrero | C6: 517814 | D6: 7090953 | E6: 204 | F6: =D6/E6 -> 34759.574 | G6: =F6/C6 -> 0.067127528 | H6: 2329571 | I6: =F6/H6 -> 0.014921019 | J6: =C6/H6 -> 0.22227869
B7: marzo | C7: 428057 | D7: 6373151 | E7: 215 | F7: =D7/E7 -> 29642.563 | G7: =F7/C7 -> 0.069249102 | H7: 1751127 | I7: =F7/H7 -> 0.016927706 | J7: =C7/H7 -> 0.24444658
B8: abril | C8: 420763 | D8: 6573606 | E8: 230 | F8: =D8/E8 -> 28580.896 | G8: =F8/C8 -> 0.067926352 | H8: 2720075 | I8: =F8/H8 -> 0.010507392 | J8: =C8/H8 -> 0.15468801
B9: mayo | C9: 406760 | D9: 9315709 | E9: 244 | F9: =D9/E9 -> 38179.135 | G9: =F9/C9 -> 0.093861577 | H9: 1147140 | I9: =F9/H9 -> 0.033282019 | J9: =C9/H9 -> 0.35458619
B10: junio | C10: 396362 | D10: 9353226 | E10: 257 | F10: =D10/E10 -> 36393.875 | G10: =F10/C10 -> 0.09181979 | H10: 2441754 | I10: =F10/H10 -> 0.014904808 | J10: =C10/H10 -> 0.16232675
B11: julio | C11: 500485 | D11: 12304968 | E11: 286 | F11: =D11/E11 -> 43024.364 | G11: =F11/C11 -> 0.085965341 | H11: 2751160 | I11: =F11/H11 -> 0.015638626 | J11: =C11/H11 -> 0.18191781
B12: agosto | C12: 479515 | D12: 14203388 | E12: 365 | F12: =D12/E12 -> 38913.392 | G12: =F12/C12 -> 0.081151563 | H12: 3263219 | I12: =F12/H12 -> 0.011924848 | J12: =C12/H12 -> 0.14694539
B13: septiembre | C13: 430806 | D13: 14440337 | E13: 367.1 | F13: =D13/E13 -> 39336.249 | G13: =F13/C13 -> 0.091308498 | H13: 2874751 | I13: =F13/H13 -> 0.013683359 | J13: =C13/H13 -> 0.14985854
B14: octubre | C14: =127055+162760+60770 -> 350585 | D14: 14101011 | E14: 365.5 | F14: =D14/E14 -> 38580.057 | G14: =F14/C14 -> 0.1100448 | H14: 2692960 | I14: =F14/H14 -> 0.014326265 | J14: =C14/H14 -> 0.13018574
B15: noviembre | C15: =103295+152185+54495 -> 309975 | D15: 13909727 | E15: 378.5 | F15: =D15/E15 -> 36749.609 | G15: =F15/C15 -> 0.11855669 | H15: 1379860 | I15: =F15/H15 -> 0.026632853 | J15: =C15/H15 -> 0.22464236
B16: diciembre | C16: 109030 | D16: 10164235 | E16: 790 | F16: =D16/E16 -> 12866.12 | G16: =F16/C16 -> 0.11800532 | H16: 1156484 | I16: =F16/H16 -> 0.011125204 | J16: =C16/H16 -> 0.094277137
B18: total | C18: =SUM(C5:C14) -> 4196094 | F18: =SUM(F5:F14) -> 346942.85 | H18: =SUM(H5:H16) -> 25622951
B19: promedio | G19: =(G5*F5+G6*F6+G7*F7+G8*F8+G9*F9+G10*F10+G11*F11+G12*F12+G13*F13+G14*F14)/F18 -> 0.084701112 | I19: =(I5*H5+I6*H6+I7*H7+I8*H8+I9*H9+I10*H10+I11*H11+I12*H12+I13*H13+I14*H14)/H18 -> 0.013540316 | J19: =(J5*H5+J6*H6+J7*H7+J8*H8+J9*H9+J10*H10+J11*J11+J12*H12+J13*H13+J14*H14)/H18 -> 0.14423042
B21: medidor | C21: 107552 | D21: ( conectado sector sopladoras )
C22: Kw-h | D22: $ | E22: $ x U$S | F22: U$S | G22: U$S / Kw-h | H22: unidades | I22: U$S / unidad | J22: Kw-h / udades
B23: enero
B24: febrero
B25: marzo
B26: abril
B27: mayo
B28: junio
B29: julio
B30: agosto | C30: 31200 | D30: 3617865 | E30: 365 | F30: =D30/E30 -> 9911.9589 | G30: =(F30+F31)/C30/2 -> 0.28809218 | H30: 0
B31: septiembre | D31: 2960659 | E31: 367.1 | F31: =D31/E31 -> 8064.9932 | G31: =G30 -> 0.28809218 | H31: 937 | I31: =F31/H31 -> 8.6072499 | J31: =C30/H31 -> 33.297759
B32: octubre | C32: 3600 | D32: 3254758 | E32: 365.5 | F32: =D32/E32 -> 8904.9466 | G32: =F32/C32 -> 2.4735963 | H32: 1233 | I32: =F32/H32 -> 7.222179 | J32: =C32/H32 -> 2.919708
B33: noviembre | C33: 3600 | D33: 2960659 | E33: 365.5 | F33: =D33/E33 -> 8100.2982 | G33: =F33/C33 -> 2.2500828 | H33: 26717 | I33: =F33/H33 -> 0.30318891
B34: diciembre | C34: 1 | D34: 2960658.9 | E34: 790 | F34: =D34/E34 -> 3747.6695 | G34: =F34/C34 -> 3747.6695 | H34: 0
B36: total | C36: =SUM(C23:C32) -> 34800 | F36: =SUM(F23:F32) -> 26881.899 | H36: =SUM(H23:H34) -> 28887
B37: promedio | G37: =(G23*F23+G24*F24+G25*F25+G26*F26+G27*F27+G28*F28+G29*F29+G30*F30+G31*F31+G32*F32)/F36 -> 1.0120662 | I37: =(I23*H23+I24*H24+I25*H25+I26*H26+I27*H27+I28*H28+I29*H29+I30*H30+I31*H31+I32*H32)/H36 -> 0.58745941 | J37: =(J23*H23+J24*H24+J25*H25+J26*H26+J27*H27+J28*H28+J29*J29+J30*H30+J31*H31+J32*H32)/H36 -> 1.2046942
B39: ENERGIA ELECTRICA 2023
B40: con ambos medidores
C41: Kw-h | D41: $ | E41: $ x U$S | F41: U$S | G41: U$S / Kw-h | H41: lts- kg | I41: U$S / lt-kg | J41: Kw-h / lt-kg
B42: enero | C42: 264947 | D42: 3594025 | E42: 184 | F42: =D42/E42 -> 19532.745 | G42: =F42/C42 -> 0.073723215 | H42: 1114850 | I42: =F42/H42 -> 0.017520514 | J42: =C42/H42 -> 0.2376526 | K42: 1 medidor
B43: febrero | C43: 517814 | D43: 7090953 | E43: 204 | F43: =D43/E43 -> 34759.574 | G43: =F43/C43 -> 0.067127528 | H43: 2329571 | I43: =F43/H43 -> 0.014921019 | J43: =C43/H43 -> 0.22227869 | K43: 1 medidor
B44: marzo | C44: 428057 | D44: 6373151 | E44: 215 | F44: =D44/E44 -> 29642.563 | G44: =F44/C44 -> 0.069249102 | H44: 1751127 | I44: =F44/H44 -> 0.016927706 | J44: =C44/H44 -> 0.24444658 | K44: 1 medidor
B45: abril | C45: 420763 | D45: 6573606 | E45: 230 | F45: =D45/E45 -> 28580.896 | G45: =F45/C45 -> 0.067926352 | H45: 2720075 | I45: =F45/H45 -> 0.010507392 | J45: =C45/H45 -> 0.15468801 | K45: 1 medidor
...

Sheet graficos 23
B1: 2023
B2: consumo energía eléctrica | L2: consumo energía eléctrica por unidad producida
B3: medidor producción | L3: medidor producción
C4: Kw-h | M4: Kw-h/ lt-kg
B5: enero | C5: =datos23!C5 -> 264947 | L5: enero | M5: =datos23!J42 -> 0.2376526
B6: febrero | C6: =datos23!C6 -> 517814 | L6: febrero | M6: =datos23!J43 -> 0.22227869
B7: marzo | C7: =datos23!C7 -> 428057 | L7: marzo | M7: =datos23!J44 -> 0.24444658
B8: abril | C8: =datos23!C8 -> 420763 | L8: abril | M8: =datos23!J45 -> 0.15468801
B9: mayo | C9: =datos23!C9 -> 406760 | L9: mayo | M9: =datos23!J46 -> 0.35458619
B10: junio | C10: =datos23!C10 -> 396362 | L10: junio | M10: =datos23!J47 -> 0.16232675
B11: julio | C11: =datos23!C11 -> 500485 | L11: julio | M11: =datos23!J48 -> 0.18191781
B12: agosto | C12: =datos23!C12 -> 479515 | L12: agosto | M12: =datos23!J49 -> 0.15172595
B13: septiembre | C13: =datos23!C13 -> 430806 | L13: septiembre | M13: =datos23!J50 -> 0.1552851
B14: octubre | C14: =datos23!C14 -> 350585 | L14: octubre | M14: =datos23!J51 -> 0.13146237
B15: noviembre | C15: =datos23!C15 -> 309975 | L15: noviembre | M15: =datos23!J52 -> 0.22293483
B16: diciembre | C16: =datos23!C16 -> 109030 | L16: diciembre | M16: =datos23!J53 -> 0.17209922
B17: promedio | C17: =AVERAGE(C5:C16) -> 384591.58 | L17: promedio | M17: =AVERAGE(M5:M16) -> 0.19928368
B19: costo energía eléctrica por unidad consumida | L19: con ambos medidores
C20: U$S / Kw-h | M20: U$S / Kw-h
B21: enero | C21: =datos23!G5 -> 0.073723215 | L21: enero | M21: =datos23!G42 -> 0.073723215
B22: febrero | C22: =datos23!G6 -> 0.067127528 | L22: febrero | M22: =datos23!G43 -> 0.067127528
B23: marzo | C23: =datos23!G7 -> 0.069249102 | L23: marzo | M23: =datos23!G44 -> 0.069249102
B24: abril | C24: =datos23!G8 -> 0.067926352 | L24: abril | M24: =datos23!G45 -> 0.067926352
B25: mayo | C25: =datos23!G9 -> 0.093861577 | L25: mayo | M25: =datos23!G46 -> 0.093861577
B26: junio | C26: =datos23!G10 -> 0.09181979 | L26: junio | M26: =datos23!G47 -> 0.09181979
B27: julio | C27: =datos23!G11 -> 0.085965341 | L27: julio | M27: =datos23!G48 -> 0.085965341
B28: agosto | C28: =datos23!G12 -> 0.081151563 | L28: agosto | M28: =datos23!G49 -> 0.098614162
B29: septiembre | C29: =datos23!G13 -> 0.091308498 | L29: septiembre | M29: =datos23!G50 -> 0.10618415
B30: octubre | C30: =datos23!G14 -> 0.1100448 | L30: octubre | M30: =datos23!G51 -> 0.13406837
B31: noviembre | C31: =datos23!G15 -> 0.11855669 | L31: noviembre | M31: =datos23!G52 -> 0.14719607
B32: diciembre | C32: =datos23!G16 -> 0.11800532 | L32: diciembre | M32: =datos23!G53 -> 0.083473985
B33: promedio pond | C33: =datos23!G19 -> 0.084701112 | L33: promedio ponderado | M33: =datos23!G56 -> 0.098000567
B35: costo unitario energía eléctrica por unidad producida
C36: U$S / lt-kg | M36: U$S / lt-kg
B37: enero | C37: =datos23!I5 -> 0.017520514 | L37: enero | M37: =datos23!I42 -> 0.017520514
B38: febrero | C38: =datos23!I6 -> 0.014921019 | L38: febrero | M38: =datos23!I43 -> 0.014921019
B39: marzo | C39: =datos23!I7 -> 0.016927706 | L39: marzo | M39: =datos23!I44 -> 0.016927706
B40: abril | C40: =datos23!I8 -> 0.010507392 | L40: abril | M40: =datos23!I45 -> 0.010507392
B41: mayo | C41: =datos23!I9 -> 0.033282019 | L41: mayo | M41: =datos23!I46 -> 0.033282019
B42: junio | C42: =datos23!I10 -> 0.014904808 | L42: junio | M42: =datos23!I47 -> 0.014904808
...

Sheet datos24
B2: ENERGIA ELECTRICA 2024
B3: medidor | C3: 4156946
C4: Kw-h | D4: $ | E4: $ x U$S | F4: U$S | G4: U$S / Kw-h | H4: lts- kg | I4: U$S / lt-kg | J4: Kw-h / lt-kg
B5: enero | C5: =97880+151505+47350 -> 296735 | D5: 18286055 | E5: 805.5 | F5: =D5/E5 -> 22701.496 | G5: =F5/C5 -> 0.076504276 | H5: 2196843 | I5: =F5/H5 -> 0.010333691 | J5: =C5/H5 -> 0.13507338
B6: febrero | C6: =111425+169940+66270 -> 347635 | D6: 29363562 | E6: 841.7 | F6: =D6/E6 -> 34886.019 | G6: =F6/C6 -> 0.10035244 | H6: 2969960 | I6: =F6/H6 -> 0.011746293 | J6: =C6/H6 -> 0.1170504
B7: marzo | C7: 319955 | D7: 32216987 | E7: 858 | F7: =D7/E7 -> 37548.936 | G7: =F7/C7 -> 0.11735693 | H7: 1867230 | I7: =F7/H7 -> 0.020109433 | J7: =C7/H7 -> 0.17135275
B8: abril | C8: 313960 | D8: 31715558 | E8: 888 | F8: =D8/E8 -> 35715.718 | G8: =F8/C8 -> 0.11375882 | H8: 2025427 | I8: =F8/H8 -> 0.017633674 | J8: =C8/H8 -> 0.15500929
B9: mayo | C9: 370005 | D9: 35697362 | E9: 906 | F9: =D9/E9 -> 39401.062 | G9: =F9/C9 -> 0.10648792 | H9: 3160491 | I9: =F9/H9 -> 0.012466753 | J9: =C9/H9 -> 0.117072
B10: junio | C10: 249650 | D10: 39545373 | E10: 923 | F10: =D10/E10 -> 42844.391 | G10: =F10/C10 -> 0.17161783 | H10: 1746477 | I10: =F10/H10 -> 0.024531895 | J10: =C10/H10 -> 0.14294491
B11: julio | C11: 381437 | D11: 46807707 | E11: 942 | F11: =D11/E11 -> 49689.71 | G11: =F11/C11 -> 0.13026977 | H11: 2603936 | I11: =F11/H11 -> 0.019082539 | J11: =C11/H11 -> 0.14648478
B12: agosto | C12: 371130 | D12: 47316894 | E12: 961 | F12: =D12/E12 -> 49237.143 | G12: =F12/C12 -> 0.13266818 | H12: 1407612 | I12: =F12/H12 -> 0.034979201 | J12: =C12/H12 -> 0.2636593
B13: septiembre | C13: 311615 | D13: 44268944 | E13: 991 | F13: =D13/E13 -> 44670.983 | G13: =F13/C13 -> 0.14335312 | H13: 2218621 | I13: =F13/H13 -> 0.020134571 | J13: =C13/H13 -> 0.14045436
B14: octubre | C14: 374735 | D14: 59088960 | E14: 972 | F14: =D14/E14 -> 60791.111 | G14: =F14/C14 -> 0.16222427 | H14: 2887852 | I14: =F14/H14 -> 0.021050632 | J14: =C14/H14 -> 0.12976254
B15: noviembre | C15: 409235 | D15: 54475169 | E15: 979 | F15: =D15/E15 -> 55643.686 | G15: =F15/C15 -> 0.13597001 | H15: 2949273 | I15: =F15/H15 -> 0.018866916 | J15: =C15/H15 -> 0.13875792
B16: diciembre | C16: 230130 | D16: 37072281 | E16: 1002 | F16: =D16/E16 -> 36998.284 | G16: =F16/C16 -> 0.16077124 | H16: 1062953 | I16: =F16/H16 -> 0.034807075 | J16: =C16/H16 -> 0.21650064
B18: total | C18: =SUM(C5:C16) -> 3976222 | F18: =SUM(F5:F16) -> 510128.54 | H18: =SUM(H5:H16) -> 27096675
B19: promedio | G19: =(G5*F5+G6*F6+G7*F7+G8*F8+G9*F9+G10*F10+G11*F11+G12*F12+G13*F13+G14*F14+G15*F15+G16*F16)/F18 -> 0.13337968 | I19: =(I5*H5+I6*H6+I7*H7+I8*H8+I9*H9+I10*H10+I11*H11+I12*H12+I13*H13+I14*H14+H15*I15+H16*I16)/H18 -> 0.018826241 | J19: =(J5*H5+J6*H6+J7*H7+J8*H8+J9*H9+J10*H10+J11*J11+J12*H12+J13*H13+J14*H14+J15*H15+J16*H16)/H18 -> 0.13266517
B21: medidor | C21: 107552 | D21: ( conectado sector sopladoras )
C22: Kw-h | D22: $ | E22: $ x U$S | F22: U$S | G22: U$S / Kw-h | H22: unidades | I22: U$S / unidad | J22: Kw-h / udades
B23: enero | C23: 1373 | D23: 5079576 | E23: 805.5 | F23: =D23/E23 -> 6306.1155 | G23: =F23/C23 -> 4.5929464 | H23: 19958 | I23: =F23/H23 -> 0.31596931 | J23: =C23/H23 -> 0.068794468
B24: febrero | C24: 1352 | D24: 5004675 | E24: 841.7 | F24: =D24/E24 -> 5945.913 | G24: =F24/C24 -> 4.3978647 | H24: 15358 | I24: =F24/H24 -> 0.38715412 | J24: =C24/H24 -> 0.088032296
B25: marzo | C25: 1863 | D25: 6894514 | E25: 858 | F25: =D25/E25 -> 8035.5641 | G25: =F25/C25 -> 4.3132389 | H25: 0
B26: abril | C26: 1863 | D26: 6894514 | E26: 888 | F26: =D26/E26 -> 7764.0923 | G26: =F26/C26 -> 4.1675214 | H26: 11472 | I26: =F26/H26 -> 0.67678629 | J26: =C26/H26 -> 0.1623954
B27: mayo | C27: 2052 | D27: 7593209 | E27: 906 | F27: =D27/E27 -> 8381.0254 | G27: =F27/C27 -> 4.0843204 | H27: 11664 | I27: =F27/H27 -> 0.71853784 | J27: =C27/H27 -> 0.17592593
B28: junio | C28: 3948 | D28: 8967410 | E28: 923 | F28: =D28/E28 -> 9715.5038 | G28: =F28/C28 -> 2.4608672 | H28: 7200 | I28: =F28/H28 -> 1.3493755 | J28: =C28/H28 -> 0.54833333
B29: julio | C29: 3855 | D29: 8756736 | E29: 942 | F29: =D29/E29 -> 9295.8981 | G29: =F29/C29 -> 2.4113873 | H29: 4896 | I29: =F29/H29 -> 1.898672 | J29: =C29/H29 -> 0.78737745
B30: agosto | C30: 4032 | D30: 9157682 | E30: 961 | F30: =D30/E30 -> 9529.3257 | G30: =F30/C30 -> 2.363424 | H30: 11280 | I30: =F30/H30 -> 0.84479838 | J30: =C30/H30 -> 0.35744681
B31: septiembre | C31: 5544 | D31: 9473662 | E31: 991 | F31: =D31/E31 -> 9559.6993 | G31: =F31/C31 -> 1.7243325 | H31: 7728 | I31: =F31/H31 -> 1.2370211 | J31: =C31/H31 -> 0.7173913
B32: octubre | C32: 4932 | D32: 14342392 | E32: 972 | F32: =D32/E32 -> 14755.547 | G32: =F32/C32 -> 2.9917979 | H32: 13104 | I32: =F32/H32 -> 1.1260338 | J32: =C32/H32 -> 0.37637363
B33: noviembre | C33: 5076 | D33: 14191349 | E33: 979 | F33: =D33/E33 -> 14495.76 | G33: =F33/C33 -> 2.8557447 | H33: 34464 | I33: =F33/H33 -> 0.42060585 | J33: =C33/H33 -> 0.14728412
B34: diciembre | C34: 6084 | D34: 14447495 | E34: 1002 | F34: =D34/E34 -> 14418.658 | G34: =F34/C34 -> 2.3699306 | H34: 12480 | I34: =F34/H34 -> 1.1553412 | J34: =C34/H34 -> 0.4875
B36: total | C36: =SUM(C23:C34) -> 41974 | F36: =SUM(F23:F34) -> 118203.1 | H36: =SUM(H23:H34) -> 149604
B37: promedio | G37: =(G23*F23+G24*F24+G25*F25+G26*F26+G27*F27+G28*F28+G29*F29+G30*F30+G31*F31+G32*F32+G33*F33+G34*F34)/F36 -> 3.0574801 | I37: =(I23*H23+I24*H24+I25*H25+I26*H26+I27*H27+I28*H28+I29*H29+I30*H30+I31*H31+I32*H32+I33*H33+I34*H34)/H36 -> 0.73639433 | J37: =(J23*H23+J24*H24+J25*H25+J26*H26+J27*H27+J28*H28+J29*J29+J30*H30+J31*H31+J32*H32+J33*H33+J34*H34)/H36 -> 0.24235061
B39: ENERGIA ELECTRICA 2024
B40: con ambos medidores
B41: , | C41: Kw-h | D41: $ | E41: $ x U$S | F41: U$S | G41: U$S / Kw-h | H41: lts- kg- udades | I41: U$S / lt-kg-udad | J41: Kw-h / lt-kg
B42: enero | C42: =C5+C23 -> 298108 | D42: =D5+D23 -> 23365631 | E42: 805.5 | F42: =D42/E42 -> 29007.612 | G42: =F42/C42 -> 0.097305714 | H42: =H5+H23 -> 2216801 | I42: =F42/H42 -> 0.013085348 | J42: =C42/H42 -> 0.13447666
B43: febrero | C43: =C6+C24 -> 348987 | D43: =D6+D24 -> 34368237 | E43: =E6 -> 841.7 | F43: =D43/E43 -> 40831.932 | G43: =F43/C43 -> 0.1170013 | H43: =H6+H24 -> 2985318 | I43: =F43/H43 -> 0.013677582 | J43: =C43/H43 -> 0.11690111
B44: marzo | C44: =C7+C25 -> 321818 | D44: =D7+D25 -> 39111501 | E44: =E7 -> 858 | F44: =D44/E44 -> 45584.5 | G44: =F44/C44 -> 0.14164683 | H44: =H7+H25 -> 1867230 | I44: =F44/H44 -> 0.0244129 | J44: =C44/H44 -> 0.17235049
B45: abril | C45: =C8+C26 -> 315823 | D45: =D8+D26 -> 38610072 | E45: =E8 -> 888 | F45: =D45/E45 -> 43479.811 | G45: =F45/C45 -> 0.13767145 | H45: =H8+H26 -> 2036899 | I45: =F45/H45 -> 0.021346081 | J45: =C45/H45 -> 0.15505089
...

Sheet graficos 24
B1: 2024
B2: consumo energía eléctrica
B3: con ambos medidores
C4: kW-h
B5: enero | C5: =datos24!C42 -> 298108
B6: febrero | C6: =datos24!C43 -> 348987
B7: marzo | C7: =datos24!C44 -> 321818
B8: abril | C8: =datos24!C45 -> 315823
B9: mayo | C9: =datos24!C46 -> 372057
B10: junio | C10: =datos24!C47 -> 253598
B11: julio | C11: =datos24!C48 -> 385292
B12: agosto | C12: =datos24!C49 -> 375162
B13: septiembre | C13: =datos24!C50 -> 317159
B14: octubre | C14: =datos24!C51 -> 379667
B15: noviembre | C15: =datos24!C52 -> 414311
B16: diciembre | C16: =datos24!C53 -> 236214
B17: promedio | C17: =AVERAGE(C5:C16) -> 334849.67
B19: costo energía eléctrica por unidad consumida
C20: U$S / Kw-h
B21: enero | C21: =datos24!G42 -> 0.097305714
B22: febrero | C22: =datos24!G43 -> 0.1170013
B23: marzo | C23: =datos24!G44 -> 0.14164683
B24: abril | C24: =datos24!G45 -> 0.13767145
B25: mayo | C25: =datos24!G46 -> 0.12842679
B26: junio | C26: =datos24!G47 -> 0.20725674
B27: julio | C27: =datos24!G48 -> 0.15309326
B28: agosto | C28: =datos24!G49 -> 0.15664291
B29: septiembre | C29: =datos24!G50 -> 0.17098894
B30: octubre | C30: =datos24!G51 -> 0.19898137
B31: noviembre | C31: =datos24!G52 -> 0.16929178
B32: diciembre | C32: =datos24!G53 -> 0.21767102
B33: promedio pond | C33: =datos24!G19 -> 0.13337968
B35: costo unitario energía eléctrica por unidad producida
C36: U$S / lt-kg
B37: enero | C37: =datos24!I42 -> 0.013085348
B38: febrero | C38: =datos24!I43 -> 0.013677582
B39: marzo | C39: =datos24!I44 -> 0.0244129
B40: abril | C40: =datos24!I45 -> 0.021346081
B41: mayo | C41: =datos24!I46 -> 0.015062974
B42: junio | C42: =datos24!I47 -> 0.029971252
...

Sheet datos25
B2: ENERGIA ELECTRICA 2025
B3: medidor | C3: 4156946 | D3: A300-400-500-600-700-1000-1100 | G3: incluye líquidos evaporados y fardos
C4: Kw-h | D4: $ | E4: $ x U$S | F4: U$S | G4: U$S / Kw-h | H4: lts- kg | I4: U$S / lt-kg | J4: Kw-h / lt-kg | K4: Pot contrat 1100
B5: enero | C5: 148340 | D5: 30891849 | E5: 1074 | F5: =D5/E5 -> 28763.36 | G5: =F5/C5 -> 0.19390158 | H5: 365645 | I5: =F5/H5 -> 0.078664717 | J5: =C5/H5 -> 0.40569405
B6: febrero | C6: 161773 | D6: 35294347 | E6: 1084 | F6: =D6/E6 -> 32559.361 | G6: =F6/C6 -> 0.20126573 | H6: 419403 | I6: =F6/H6 -> 0.077632637 | J6: =C6/H6 -> 0.38572209
B7: marzo | C7: 151287 | D7: 36118133 | E7: 1094 | F7: =D7/E7 -> 33014.747 | G7: =F7/C7 -> 0.21822593 | H7: 422762 | I7: =F7/H7 -> 0.078092986 | J7: =C7/H7 -> 0.35785383
B8: abril | C8: 213995 | D8: 44270737 | E8: 1114 | F8: =D8/E8 -> 39740.338 | G8: =F8/C8 -> 0.18570685 | H8: 1518390 | I8: =F8/H8 -> 0.026172682 | J8: =C8/H8 -> 0.14093546
B9: mayo | C9: 219258.4 | D9: 45818312 | E9: 1162 | F9: =D9/E9 -> 39430.561 | G9: =F9/C9 -> 0.17983603 | H9: 2413571 | I9: =F9/H9 -> 0.016337021 | J9: =C9/H9 -> 0.090843982 | K9: 681
B10: junio | C10: 256315 | D10: 55417002 | E10: 1213 | F10: =D10/E10 -> 45685.904 | G10: =F10/C10 -> 0.17824124 | H10: 2436084 | I10: =F10/H10 -> 0.01875383 | J10: =C10/H10 -> 0.10521599 | K10: 713
B11: julio | C11: 266424.95 | D11: 58752903 | E11: 1325 | F11: =D11/E11 -> 44341.814 | G11: =F11/C11 -> 0.16643266 | H11: 2656123 | I11: =F11/H11 -> 0.016694187 | J11: =C11/H11 -> 0.10030595 | K11: 680
B12: agosto | C12: 238700 | D12: 50981119 | E12: 1360 | F12: =D12/E12 -> 37486.117 | G12: =F12/C12 -> 0.1570428 | H12: 2590577 | I12: =F12/H12 -> 0.01447018 | J12: =C12/H12 -> 0.092141635 | K12: 616
B13: septiembre | C13: =96720+41160+118750 -> 256630 | D13: 67487673 | E13: 1400 | F13: =D13/E13 -> 48205.481 | G13: =F13/C13 -> 0.1878404 | H13: 2522489 | I13: =F13/H13 -> 0.019110284 | J13: =C13/H13 -> 0.10173682 | K13: 584
B14: octubre | C14: 231633 | D14: 59450626 | E14: 1435 | F14: =D14/E14 -> 41429.008 | G14: =F14/C14 -> 0.17885624 | H14: 2279040 | I14: =F14/H14 -> 0.018178271 | J14: =C14/H14 -> 0.10163622 | K14: 582-570
B15: noviembre | C15: =89355+44785+136145 -> 270285 | D15: 64709304 | E15: 1450 | F15: =D15/E15 -> 44627.106 | G15: =F15/C15 -> 0.1651113 | H15: 1575989 | I15: =F15/H15 -> 0.02831689 | J15: =C15/H15 -> 0.17150183 | K15: 655-722
B16: diciembre | C16: 202899 | D16: 56550984 | E16: 1464 | F16: =D16/E16 -> 38627.721 | G16: =F16/C16 -> 0.19037906 | H16: 1094280 | I16: =F16/H16 -> 0.035299669 | J16: =C16/H16 -> 0.18541781 | K16: 609-685
B18: total | C18: =SUM(C5:C16) -> 2617540.4 | F18: =SUM(F5:F16) -> 473911.52 | H18: =SUM(H5:H16) -> 20294353
B19: promedio | G19: =(G5*F5+G6*F6+G7*F7+G8*F8+G9*F9+G10*F10+G11*F11+G12*F12+G13*F13+G14*F14+G15*F15+G16*F16)/F18 -> 0.18231925 | I19: =(I5*H5+I6*H6+I7*H7+I8*H8+I9*H9+I10*H10+I11*H11+I12*H12+I13*H13+I14*H14+H15*I15+H16*I16)/H18 -> 0.023351891 | J19: =(J5*H5+J6*H6+J7*H7+J8*H8+J9*H9+J10*H10+J11*J11+J12*H12+J13*H13+J14*H14+J15*H15+J16*H16)/H18 -> 0.11585072
B21: medidor | C21: 107552 | D21: A800, A900, Sopladoras y picado bidones
C22: Kw-h | D22: $ | E22: $ x U$S | F22: U$S | G22: U$S / Kw-h | H22: unidades | I22: U$S / unidad | J22: Kw-h / udades | K22: Pot contrat 1000
B23: enero | C23: 61020 | D23: 28478675 | E23: 1074 | F23: =D23/E23 -> 26516.457 | G23: =F23/C23 -> 0.43455354 | H23: =122650+127099 -> 249749 | I23: =F23/H23 -> 0.10617243 | J23: =C23/H23 -> 0.2443253
B24: febrero | C24: 198072 | D24: 36739215 | E24: 1084 | F24: =D24/E24 -> 33892.265 | G24: =F24/C24 -> 0.17111083 | H24: 130227 | I24: =F24/H24 -> 0.26025528 | J24: =C24/H24 -> 1.5209749
B25: marzo | C25: 179748 | D25: 33949544 | E25: 1094 | F25: =D25/E25 -> 31032.49 | G25: =F25/C25 -> 0.17264442 | H25: =139761+7200+1867 -> 148828 | I25: =F25/H25 -> 0.20851244 | J25: =C25/H25 -> 1.2077566
B26: abril | C26: 144900 | D26: 29441972 | E26: 1114 | F26: =D26/E26 -> 26429.059 | G26: =F26/C26 -> 0.18239516 | H26: 286814 | I26: =F26/H26 -> 0.092147033 | J26: =C26/H26 -> 0.50520546
B27: mayo | C27: 142992 | D27: 29573432 | E27: 1162 | F27: =D27/E27 -> 25450.458 | G27: =F27/C27 -> 0.17798518 | H27: 405306 | I27: =F27/H27 -> 0.062793192 | J27: =C27/H27 -> 0.35280011 | K27: 259
B28: junio | C28: 153720 | D28: 33909050 | E28: 1213 | F28: =D28/E28 -> 27954.699 | G28: =F28/C28 -> 0.18185466 | H28: 368643 | I28: =F28/H28 -> 0.075831357 | J28: =C28/H28 -> 0.41698879 | K28: 259
B29: julio | C29: 180000 | D29: 37054823 | E29: 1325 | F29: =D29/E29 -> 27965.904 | G29: =F29/C29 -> 0.15536613 | H29: 368859 | I29: =F29/H29 -> 0.075817329 | J29: =C29/H29 -> 0.48799135 | K29: 302
B30: agosto | C30: 137160 | D30: 34918532 | E30: 1360 | F30: =D30/E30 -> 25675.391 | G30: =F30/C30 -> 0.187193 | H30: 449859 | I30: =F30/H30 -> 0.057074309 | J30: =C30/H30 -> 0.30489553 | K30: 288
B31: septiembre | C31: =34740+28584+79704+8820+7344+19944 -> 179136 | D31: 43973571 | E31: 1400 | F31: =D31/E31 -> 31409.694 | G31: =F31/C31 -> 0.17533993 | H31: 373747 | I31: =F31/H31 -> 0.084039988 | J31: =C31/H31 -> 0.47929749 | K31: 288-302
B32: octubre | C32: 173484 | D32: 40846829 | E32: 1435 | F32: =D32/E32 -> 28464.689 | G32: =F32/C32 -> 0.16407674 | H32: 436798 | I32: =F32/H32 -> 0.065166711 | J32: =C32/H32 -> 0.39717215 | K32: 302-317
B33: noviembre | C33: =33696+30528+79272+8496+7741+19655 -> 179388 | D33: 41042090 | E33: 1450 | F33: =D33/E33 -> 28304.89 | G33: =F33/C33 -> 0.15778586 | H33: 357081 | I33: =F33/H33 -> 0.07926742 | J33: =C33/H33 -> 0.50237341 | K33: 302
B34: diciembre | C34: 125748 | D34: 36104730 | E34: 1464 | F34: =D34/E34 -> 24661.701 | G34: =F34/C34 -> 0.19612002 | H34: 321269 | I34: =F34/H34 -> 0.0767634 | J34: =C34/H34 -> 0.39141031 | K34: 302
B36: total | C36: =SUM(C23:C34) -> 1855368 | F36: =SUM(F23:F34) -> 337757.7 | H36: =SUM(H23:H34) -> 3897180
B37: promedio | G37: =(G23*F23+G24*F24+G25*F25+G26*F26+G27*F27+G28*F28+G29*F29+G30*F30+G31*F31+G32*F32+G33*F33+G34*F34)/F36 -> 0.19465288 | I37: =(I23*H23+I24*H24+I25*H25+I26*H26+I27*H27+I28*H28+I29*H29+I30*H30+I31*H31+I32*H32+I33*H33+I34*H34)/H36 -> 0.086667205 | J37: =(J23*H23+J24*H24+J25*H25+J26*H26+J27*H27+J28*H28+J29*J29+J30*H30+J31*H31+J32*H32+J33*H33+J34*H34)/H36 -> 0.42989244
B39: ENERGIA ELECTRICA 2025
B40: con ambos medidores
C41: Kw-h | D41: $ | E41: $ x U$S | F41: U$S | G41: U$S / Kw-h | H41: lts- kg- udades | I41: U$S / lt-kg-udad | J41: Kw-h / lt-kg | M41: Kw-h | N41: U$S | O41: U$S / Kw-h | P41: lts- kg- udades | Q41: U$S / lt-kg-udad
B42: enero | C42: =C5+C23 -> 209360 | D42: =D5+D23 -> 59370524 | E42: =E5 -> 1074 | F42: =D42/E42 -> 55279.818 | G42: =F42/C42 -> 0.26404193 | H42: =H5+H23 -> 615394 | I42: =F42/H42 -> 0.089828334 | J42: =C42/H42 -> 0.34020481 | L42: enero | M42: =C42 -> 209360 | N42: =F42 -> 55279.818 | O42: =N42/M42 -> 0.26404193 | P42: =H42 -> 615394 | Q42: =N42/P42 -> 0.089828334
B43: febrero | C43: =C6+C24 -> 359845 | D43: =D6+D24 -> 72033562 | E43: =E6 -> 1084 | F43: =D43/E43 -> 66451.625 | G43: =F43/C43 -> 0.18466736 | H43: =H6+H24 -> 549630 | I43: =F43/H43 -> 0.12090247 | J43: =C43/H43 -> 0.65470407 | L43: febrero | M43: =C43 -> 359845 | N43: =F43 -> 66451.625 | O43: =N43/M43 -> 0.18466736 | P43: =H43 -> 549630 | Q43: =N43/P43 -> 0.12090247
B44: marzo | C44: =C7+C25 -> 331035 | D44: =D7+D25 -> 70067677 | E44: =E7 -> 1094 | F44: =D44/E44 -> 64047.237 | G44: =F44/C44 -> 0.19347573 | H44: =H7+H25 -> 571590 | I44: =F44/H44 -> 0.11205101 | J44: =C44/H44 -> 0.57914764 | L44: marzo | M44: =C44 -> 331035 | N44: =F44 -> 64047.237 | O44: =N44/M44 -> 0.19347573 | P44: =H44 -> 571590 | Q44: =N44/P44 -> 0.11205101
B45: abril | C45: =C8+C26 -> 358895 | D45: =D8+D26 -> 73712709 | E45: =E8 -> 1114 | F45: =D45/E45 -> 66169.398 | G45: =F45/C45 -> 0.1843698 | H45: =H8+H26 -> 1805204 | I45: =F45/H45 -> 0.036654803 | J45: =C45/H45 -> 0.19881133 | L45: abril | M45: =C45 -> 358895 | N45: =F45 -> 66169.398 | O45: =N45/M45 -> 0.1843698 | P45: =H45 -> 1805204 | Q45: =N45/P45 -> 0.036654803
...

Sheet graficos 25
B1: 2025
B2: consumo energía eléctrica | J2: consumo energía eléctrica | R2: consumo energía eléctrica
B3: medidor producción - servicios | J3: medidor sopladora-A800-A900 | R3: ambos medidores
C4: kW-h | K4: kW-h | S4: kW-h
B5: enero | C5: =datos25!C5 -> 148340 | J5: enero | K5: =datos25!C23 -> 61020 | R5: enero | S5: =datos25!C42 -> 209360
B6: febrero | C6: =datos25!C6 -> 161773 | J6: febrero | K6: =datos25!C24 -> 198072 | R6: febrero | S6: =datos25!C43 -> 359845
B7: marzo | C7: =datos25!C7 -> 151287 | J7: marzo | K7: =datos25!C25 -> 179748 | R7: marzo | S7: =datos25!C44 -> 331035
B8: abril | C8: =datos25!C8 -> 213995 | J8: abril | K8: =datos25!C26 -> 144900 | R8: abril | S8: =datos25!C45 -> 358895
B9: mayo | C9: =datos25!C9 -> 219258.4 | J9: mayo | K9: =datos25!C27 -> 142992 | R9: mayo | S9: =datos25!C46 -> 362250.4
B10: junio | C10: =datos25!C10 -> 256315 | J10: junio | K10: =datos25!C28 -> 153720 | R10: junio | S10: =datos25!C47 -> 410035
B11: julio | C11: =datos25!C11 -> 266424.95 | J11: julio | K11: =datos25!C29 -> 180000 | R11: julio | S11: =datos25!C48 -> 446424.95
B12: agosto | C12: =datos25!C12 -> 238700 | J12: agosto | K12: =datos25!C30 -> 137160 | R12: agosto | S12: =datos25!C49 -> 375860
B13: septiembre | C13: =datos25!C13 -> 256630 | J13: septiembre | K13: =datos25!C31 -> 179136 | R13: septiembre | S13: =datos25!C50 -> 435766
B14: octubre | C14: =datos25!C14 -> 231633 | J14: octubre | K14: =datos25!C32 -> 173484 | R14: octubre | S14: =datos25!C51 -> 405117
B15: noviembre | C15: =datos25!C15 -> 270285 | J15: noviembre | K15: =datos25!C33 -> 179388 | R15: noviembre | S15: =datos25!C52 -> 449673
B16: diciembre | C16: =datos25!C16 -> 202899 | J16: diciembre | K16: =datos25!C34 -> 125748 | R16: diciembre | S16: =datos25!C53 -> 328647
B17: promedio | C17: =AVERAGE(C5:C16) -> 218128.36 | J17: promedio | K17: =AVERAGE(K5:K16) -> 154614 | R17: promedio | S17: =AVERAGE(S5:S16) -> 372742.36
B19: costo energía eléctrica por unidad consumida | J19: costo energía eléctrica por unidad consumida | R19: costo energía eléctrica por unidad consumida
C20: U$S / Kw-h | K20: U$S / Kw-h | S20: U$S / Kw-h
B21: enero | C21: =datos25!G5 -> 0.19390158 | J21: enero | K21: =datos25!G23 -> 0.43455354 | R21: enero | S21: =datos25!G42 -> 0.26404193
B22: febrero | C22: =datos25!G6 -> 0.20126573 | J22: febrero | K22: =datos25!G24 -> 0.17111083 | R22: febrero | S22: =datos25!G43 -> 0.18466736
B23: marzo | C23: =datos25!G7 -> 0.21822593 | J23: marzo | K23: =datos25!G25 -> 0.17264442 | R23: marzo | S23: =datos25!G44 -> 0.19347573
B24: abril | C24: =datos25!G8 -> 0.18570685 | J24: abril | K24: =datos25!G26 -> 0.18239516 | R24: abril | S24: =datos25!G45 -> 0.1843698
B25: mayo | C25: =datos25!G9 -> 0.17983603 | J25: mayo | K25: =datos25!G27 -> 0.17798518 | R25: mayo | S25: =datos25!G46 -> 0.17511193
B26: junio | C26: =datos25!G10 -> 0.17824124 | J26: junio | K26: =datos25!G28 -> 0.18185466 | R26: junio | S26: =datos25!G47 -> 0.1795959
B27: julio | C27: =datos25!G11 -> 0.16643266 | J27: julio | K27: =datos25!G29 -> 0.15536613 | R27: julio | S27: =datos25!G48 -> 0.1619706
B28: agosto | C28: =datos25!G12 -> 0.1570428 | J28: agosto | K28: =datos25!G30 -> 0.187193 | R28: agosto | S28: =datos25!G49 -> 0.1680453
B29: septiembre | C29: =datos25!G13 -> 0.1878404 | J29: septiembre | K29: =datos25!G31 -> 0.17533993 | R29: septiembre | S29: =datos25!G50 -> 0.17640161
B30: octubre | C30: =datos25!G14 -> 0.17885624 | J30: octubre | K30: =datos25!G32 -> 0.16407674 | R30: octubre | S30: =datos25!G51 -> 0.17252719
B31: noviembre | C31: =datos25!G15 -> 0.1651113 | J31: noviembre | K31: =datos25!G33 -> 0.15778586 | R31: noviembre | S31: =datos25!G52 -> 0.16218896
B32: diciembre | C32: =datos25!G16 -> 0.19037906 | J32: diciembre | K32: =datos25!G34 -> 0.19612002 | R32: diciembre | S32: =datos25!G53 -> 0.19257569
B33: promedio pond | C33: =datos25!G19 -> 0.18231925 | J33: promedio pond | K33: =datos25!G37 -> 0.19465288 | R33: promedio pond | S33: =datos25!G56 -> 0.18298168
B35: costo unitario energía eléctrica por unidad producida | J35: costo unitario energía eléctrica por unidad producida | R35: costo unitario energía eléctrica por unidad producida
C36: U$S / lt-kg | K36: U$S / lt-kg | S36: U$S / lt-kg
B37: enero | C37: =datos25!I5 -> 0.078664717 | J37: enero | K37: =datos25!I23 -> 0.10617243 | R37: enero | S37: =datos25!I42 -> 0.089828334
B38: febrero | C38: =datos25!I6 -> 0.077632637 | J38: febrero | K38: =datos25!I24 -> 0.26025528 | R38: febrero | S38: =datos25!I43 -> 0.12090247
B39: marzo | C39: =datos25!I7 -> 0.078092986 | J39: marzo | K39: =datos25!I25 -> 0.20851244 | R39: marzo | S39: =datos25!I44 -> 0.11205101
B40: abril | C40: =datos25!I8 -> 0.026172682 | J40: abril | K40: =datos25!I26 -> 0.092147033 | R40: abril | S40: =datos25!I45 -> 0.036654803
B41: mayo | C41: =datos25!I9 -> 0.016337021 | J41: mayo | K41: =datos25!I27 -> 0.062793192 | R41: mayo | S41: =datos25!I46 -> 0.022503417
B42: junio | C42: =datos25!I10 -> 0.01875383 | J42: junio | K42: =datos25!I28 -> 0.075831357 | R42: junio | S42: =datos25!I47 -> 0.02625589
...

Sheet datos26
A1: medidor | B1: 4156946 | C1: A300-400-500-600-700 | F1: incluye líquidos evaporados y fardos
B2: Kw-h | C2: $ | D2: $ x U$S | E2: U$S | F2: U$S / Kw-h | G2: lts- kg | H2: U$S / lt-kg | I2: Kw-h / lt-kg | J2: Pot contrat 1100
A3: enero | B3: 158465 | C3: 51279291 | D3: 1470 | E3: =C3/D3 -> 34883.871 | F3: =E3/B3 -> 0.22013613 | G3: 931160 | H3: =E3/G3 -> 0.037462811 | I3: =B3/G3 -> 0.17018021 | J3: 630
A4: febrero | B4: =89785+42270+130490+3600+1832+9823 -> 277800 | C4: 67710401 | D4: 1425 | E4: =C4/D4 -> 47516.071 | F4: =E4/B4 -> 0.17104417 | G4: 947482 | H4: =E4/G4 -> 0.05014984 | I4: =B4/G4 -> 0.29319818 | J4: 704
A5: marzo | B5: =96570+44435+125475+3897+2344+11882 -> 284603 | C5: 69098637 | D5: 1415 | E5: =C5/D5 -> 48832.959 | F5: =E5/B5 -> 0.17158273 | G5: 1232374 | H5: =E5/G5 -> 0.039625113 | I5: =B5/G5 -> 0.23093882 | J5: 701
A6: abril | B6: 230730 | C6: 61083669 | D6: 1415 | E6: =C6/D6 -> 43168.67 | F6: =E6/B6 -> 0.18709604 | G6: 884860 | H6: =E6/G6 -> 0.048785876 | I6: =B6/G6 -> 0.26075311 | J6: 662
A7: mayo
A8: junio
A9: julio
A10: agosto
A11: septiembre
A12: octubre
A13: noviembre
A14: diciembre
A16: total | B16: =SUM(B3:B14) -> 951598 | E16: =SUM(E3:E14) -> 174401.57 | G16: =SUM(G3:G14) -> 3995876
A17: promedio | F17: =(F3*E3+F4*E4+F5*E5+F6*E6+F7*E7+F8*E8+F9*E9+F10*E10+F11*E11+F12*E12+F13*E13+F14*E14)/E16 -> 0.18498759 | H17: =(H3*G3+H4*G4+H5*G5+H6*G6+H7*G7+H8*G8+H9*G9+H10*G10+H11*G11+H12*G12+G13*H13+G14*H14)/G16 -> 0.043645391 | I17: =(I3*G3+I4*G4+I5*G5+I6*G6+I7*G7+I8*G8+I9*I9+I10*G10+I11*G11+I12*G12+I13*G13+I14*G14)/G16 -> 0.23814503

Sheet graficos 26
B2: consumo energía eléctrica
B3: ambos medidores
C4: kW-h
B5: enero | C5: =datos26!C42 -> 0
B6: febrero | C6: =datos26!C43 -> 0
B7: marzo | C7: =datos26!C44 -> 0
B8: abril | C8: =datos26!C45 -> 0
B9: mayo
B10: junio
B11: julio
B12: agosto
B13: septiembre
B14: octubre
B15: noviembre
B16: diciembre
B17: promedio | C17: =AVERAGE(C5:C16) -> 0
B19: costo energía eléctrica por unidad consumida
C20: U$S / Kw-h
B21: enero | C21: =datos26!G42 -> 0
B22: febrero | C22: =datos26!G43 -> 0
B23: marzo | C23: =datos26!G44 -> 0
B24: abril | C24: =datos26!G45 -> 0
B25: mayo
B26: junio
B27: julio
B28: agosto
B29: septiembre
B30: octubre
B31: noviembre
B32: diciembre
B33: promedio pond | C33: =datos26!G56 -> 0
B35: costo unitario energía eléctrica por unidad producida
C36: U$S / lt-kg
B37: enero | C37: =datos26!I42 -> 0
B38: febrero | C38: =datos26!I43 -> 0
B39: marzo | C39: =datos26!I44 -> 0
B40: abril | C40: =datos26!I45 -> 0
B41: mayo
B42: junio
B43: julio
...
